Exception on request GET /
Traceback (most recent call last):
  File "/home/runner/Tinsml/venv/lib/python3.8/site-packages/quart/app.py", line 1489, in handle_request
    return await self.full_dispatch_request(request_context)
  File "/home/runner/Tinsml/venv/lib/python3.8/site-packages/quart/app.py", line 1514, in full_dispatch_request
    result = await self.handle_user_exception(error)
  File "/home/runner/Tinsml/venv/lib/python3.8/site-packages/quart/app.py", line 964, in handle_user_exception
    raise error
  File "/home/runner/Tinsml/venv/lib/python3.8/site-packages/quart/app.py", line 1512, in full_dispatch_request
    result = await self.dispatch_request(request_context)
  File "/home/runner/Tinsml/venv/lib/python3.8/site-packages/quart/app.py", line 1557, in dispatch_request
    return await self.ensure_async(handler)(**request_.view_args)
  File "server.py", line 19, in home
    return await render_template("home.html")
  File "/home/runner/Tinsml/venv/lib/python3.8/site-packages/quart/templating.py", line 91, in render_template
    return await _render(template, context, current_app._get_current_object())  # type: ignore
  File "/home/runner/Tinsml/venv/lib/python3.8/site-packages/quart/templating.py", line 108, in _render
    rendered_template = await template.render_async(context)
  File "/home/runner/Tinsml/venv/lib/python3.8/site-packages/jinja2/environment.py", line 1324, in render_async
    return self.environment.handle_exception()
  File "/home/runner/Tinsml/venv/lib/python3.8/site-packages/jinja2/environment.py", line 936, in handle_exception
    raise rewrite_traceback_stack(source=source)
  File "/home/runner/Tinsml/venv/lib/python3.8/site-packages/jinja2/environment.py", line 1321, in <listcomp>
    [n async for n in self.root_render_func(ctx)]  # type: ignore
  File "/home/runner/Tinsml/templates/home.html", line 1, in top-level template code
    {% extends 'base.html' %}
  File "/home/runner/Tinsml/venv/lib/python3.8/site-packages/jinja2/environment.py", line 936, in handle_exception
    raise rewrite_traceback_stack(source=source)
  File "/home/runner/Tinsml/templates/base.html", line 213, in template
    {% block cpr %}
jinja2.exceptions.TemplateSyntaxError: Unexpected end of template. Jinja was looking for the following tags: 'endblock'. The innermost block that needs to be closed is 'block'.
Exception on request GET /
Traceback (most recent call last):
  File "/home/runner/Tinsml/venv/lib/python3.8/site-packages/quart/app.py", line 1489, in handle_request
    return await self.full_dispatch_request(request_context)
  File "/home/runner/Tinsml/venv/lib/python3.8/site-packages/quart/app.py", line 1514, in full_dispatch_request
    result = await self.handle_user_exception(error)
  File "/home/runner/Tinsml/venv/lib/python3.8/site-packages/quart/app.py", line 964, in handle_user_exception
    raise error
  File "/home/runner/Tinsml/venv/lib/python3.8/site-packages/quart/app.py", line 1512, in full_dispatch_request
    result = await self.dispatch_request(request_context)
  File "/home/runner/Tinsml/venv/lib/python3.8/site-packages/quart/app.py", line 1557, in dispatch_request
    return await self.ensure_async(handler)(**request_.view_args)
  File "server.py", line 19, in home
    return await render_template("home.html")
  File "/home/runner/Tinsml/venv/lib/python3.8/site-packages/quart/templating.py", line 91, in render_template
    return await _render(template, context, current_app._get_current_object())  # type: ignore
  File "/home/runner/Tinsml/venv/lib/python3.8/site-packages/quart/templating.py", line 108, in _render
    rendered_template = await template.render_async(context)
  File "/home/runner/Tinsml/venv/lib/python3.8/site-packages/jinja2/environment.py", line 1324, in render_async
    return self.environment.handle_exception()
  File "/home/runner/Tinsml/venv/lib/python3.8/site-packages/jinja2/environment.py", line 936, in handle_exception
    raise rewrite_traceback_stack(source=source)
  File "/home/runner/Tinsml/venv/lib/python3.8/site-packages/jinja2/environment.py", line 1321, in <listcomp>
    [n async for n in self.root_render_func(ctx)]  # type: ignore
  File "/home/runner/Tinsml/templates/home.html", line 1, in top-level template code
    {% extends 'base.html' %}
  File "/home/runner/Tinsml/venv/lib/python3.8/site-packages/jinja2/environment.py", line 936, in handle_exception
    raise rewrite_traceback_stack(source=source)
  File "/home/runner/Tinsml/templates/base.html", line 213, in template
    {% block cpr %}
jinja2.exceptions.TemplateSyntaxError: Unexpected end of template. Jinja was looking for the following tags: 'endblock'. The innermost block that needs to be closed is 'block'.
Exception on request GET /
Traceback (most recent call last):
  File "/home/runner/Tinsml/venv/lib/python3.8/site-packages/quart/app.py", line 1489, in handle_request
    return await self.full_dispatch_request(request_context)
  File "/home/runner/Tinsml/venv/lib/python3.8/site-packages/quart/app.py", line 1514, in full_dispatch_request
    result = await self.handle_user_exception(error)
  File "/home/runner/Tinsml/venv/lib/python3.8/site-packages/quart/app.py", line 964, in handle_user_exception
    raise error
  File "/home/runner/Tinsml/venv/lib/python3.8/site-packages/quart/app.py", line 1512, in full_dispatch_request
    result = await self.dispatch_request(request_context)
  File "/home/runner/Tinsml/venv/lib/python3.8/site-packages/quart/app.py", line 1557, in dispatch_request
    return await self.ensure_async(handler)(**request_.view_args)
  File "server.py", line 19, in home
    return await render_template("home.html")
  File "/home/runner/Tinsml/venv/lib/python3.8/site-packages/quart/templating.py", line 91, in render_template
    return await _render(template, context, current_app._get_current_object())  # type: ignore
  File "/home/runner/Tinsml/venv/lib/python3.8/site-packages/quart/templating.py", line 108, in _render
    rendered_template = await template.render_async(context)
  File "/home/runner/Tinsml/venv/lib/python3.8/site-packages/jinja2/environment.py", line 1324, in render_async
    return self.environment.handle_exception()
  File "/home/runner/Tinsml/venv/lib/python3.8/site-packages/jinja2/environment.py", line 936, in handle_exception
    raise rewrite_traceback_stack(source=source)
  File "/home/runner/Tinsml/venv/lib/python3.8/site-packages/jinja2/environment.py", line 1321, in <listcomp>
    [n async for n in self.root_render_func(ctx)]  # type: ignore
  File "/home/runner/Tinsml/templates/home.html", line 1, in top-level template code
    {% extends 'base.html' %}
  File "/home/runner/Tinsml/venv/lib/python3.8/site-packages/jinja2/environment.py", line 936, in handle_exception
    raise rewrite_traceback_stack(source=source)
  File "/home/runner/Tinsml/templates/base.html", line 213, in template
    {% block cpr %}
jinja2.exceptions.TemplateSyntaxError: Unexpected end of template. Jinja was looking for the following tags: 'endblock'. The innermost block that needs to be closed is 'block'.
Exception on request GET /
Traceback (most recent call last):
  File "/home/runner/Tinsml/venv/lib/python3.8/site-packages/quart/app.py", line 1489, in handle_request
    return await self.full_dispatch_request(request_context)
  File "/home/runner/Tinsml/venv/lib/python3.8/site-packages/quart/app.py", line 1514, in full_dispatch_request
    result = await self.handle_user_exception(error)
  File "/home/runner/Tinsml/venv/lib/python3.8/site-packages/quart/app.py", line 964, in handle_user_exception
    raise error
  File "/home/runner/Tinsml/venv/lib/python3.8/site-packages/quart/app.py", line 1512, in full_dispatch_request
    result = await self.dispatch_request(request_context)
  File "/home/runner/Tinsml/venv/lib/python3.8/site-packages/quart/app.py", line 1557, in dispatch_request
    return await self.ensure_async(handler)(**request_.view_args)
  File "server.py", line 19, in home
    return await render_template("home.html")
  File "/home/runner/Tinsml/venv/lib/python3.8/site-packages/quart/templating.py", line 91, in render_template
    return await _render(template, context, current_app._get_current_object())  # type: ignore
  File "/home/runner/Tinsml/venv/lib/python3.8/site-packages/quart/templating.py", line 108, in _render
    rendered_template = await template.render_async(context)
  File "/home/runner/Tinsml/venv/lib/python3.8/site-packages/jinja2/environment.py", line 1324, in render_async
    return self.environment.handle_exception()
  File "/home/runner/Tinsml/venv/lib/python3.8/site-packages/jinja2/environment.py", line 936, in handle_exception
    raise rewrite_traceback_stack(source=source)
  File "/home/runner/Tinsml/venv/lib/python3.8/site-packages/jinja2/environment.py", line 1321, in <listcomp>
    [n async for n in self.root_render_func(ctx)]  # type: ignore
  File "/home/runner/Tinsml/templates/home.html", line 1, in top-level template code
    {% extends 'base.html' %}
  File "/home/runner/Tinsml/templates/base.html", line 284, in top-level template code
    <a class="navbar-item" href="{{url_for('status_redirect')}}">
  File "/home/runner/Tinsml/venv/lib/python3.8/site-packages/quart/helpers.py", line 224, in url_for
    return app_context.app.handle_url_build_error(error, endpoint, values)
  File "/home/runner/Tinsml/venv/lib/python3.8/site-packages/quart/app.py", line 894, in handle_url_build_error
    raise error
  File "/home/runner/Tinsml/venv/lib/python3.8/site-packages/quart/helpers.py", line 222, in url_for
    url = url_adapter.build(endpoint, values, method=_method, force_external=_external)
  File "/home/runner/Tinsml/venv/lib/python3.8/site-packages/werkzeug/routing.py", line 2305, in build
    raise BuildError(endpoint, values, method, self)
werkzeug.routing.BuildError: Could not build url for endpoint 'status_redirect'. Did you mean 'status' instead?
Exception on request GET /
Traceback (most recent call last):
  File "/home/runner/Tinsml/venv/lib/python3.8/site-packages/quart/app.py", line 1489, in handle_request
    return await self.full_dispatch_request(request_context)
  File "/home/runner/Tinsml/venv/lib/python3.8/site-packages/quart/app.py", line 1514, in full_dispatch_request
    result = await self.handle_user_exception(error)
  File "/home/runner/Tinsml/venv/lib/python3.8/site-packages/quart/app.py", line 964, in handle_user_exception
    raise error
  File "/home/runner/Tinsml/venv/lib/python3.8/site-packages/quart/app.py", line 1512, in full_dispatch_request
    result = await self.dispatch_request(request_context)
  File "/home/runner/Tinsml/venv/lib/python3.8/site-packages/quart/app.py", line 1557, in dispatch_request
    return await self.ensure_async(handler)(**request_.view_args)
  File "server.py", line 19, in home
    return await render_template("home.html")
  File "/home/runner/Tinsml/venv/lib/python3.8/site-packages/quart/templating.py", line 91, in render_template
    return await _render(template, context, current_app._get_current_object())  # type: ignore
  File "/home/runner/Tinsml/venv/lib/python3.8/site-packages/quart/templating.py", line 108, in _render
    rendered_template = await template.render_async(context)
  File "/home/runner/Tinsml/venv/lib/python3.8/site-packages/jinja2/environment.py", line 1324, in render_async
    return self.environment.handle_exception()
  File "/home/runner/Tinsml/venv/lib/python3.8/site-packages/jinja2/environment.py", line 936, in handle_exception
    raise rewrite_traceback_stack(source=source)
  File "/home/runner/Tinsml/venv/lib/python3.8/site-packages/jinja2/environment.py", line 1321, in <listcomp>
    [n async for n in self.root_render_func(ctx)]  # type: ignore
  File "/home/runner/Tinsml/templates/home.html", line 1, in top-level template code
    {% extends 'base.html' %}
  File "/home/runner/Tinsml/templates/base.html", line 284, in top-level template code
    <a class="navbar-item" href="{{url_for('status_redirect')}}">
  File "/home/runner/Tinsml/venv/lib/python3.8/site-packages/quart/helpers.py", line 224, in url_for
    return app_context.app.handle_url_build_error(error, endpoint, values)
  File "/home/runner/Tinsml/venv/lib/python3.8/site-packages/quart/app.py", line 894, in handle_url_build_error
    raise error
  File "/home/runner/Tinsml/venv/lib/python3.8/site-packages/quart/helpers.py", line 222, in url_for
    url = url_adapter.build(endpoint, values, method=_method, force_external=_external)
  File "/home/runner/Tinsml/venv/lib/python3.8/site-packages/werkzeug/routing.py", line 2305, in build
    raise BuildError(endpoint, values, method, self)
werkzeug.routing.BuildError: Could not build url for endpoint 'status_redirect'. Did you mean 'status' instead?
