Exception on request GET /
Traceback (most recent call last):
  File "/home/runner/Tinsml/venv/lib/python3.8/site-packages/quart/app.py", line 1489, in handle_request
    return await self.full_dispatch_request(request_context)
  File "/home/runner/Tinsml/venv/lib/python3.8/site-packages/quart/app.py", line 1514, in full_dispatch_request
    result = await self.handle_user_exception(error)
  File "/home/runner/Tinsml/venv/lib/python3.8/site-packages/quart/app.py", line 964, in handle_user_exception
    raise error
  File "/home/runner/Tinsml/venv/lib/python3.8/site-packages/quart/app.py", line 1512, in full_dispatch_request
    result = await self.dispatch_request(request_context)
  File "/home/runner/Tinsml/venv/lib/python3.8/site-packages/quart/app.py", line 1557, in dispatch_request
    return await self.ensure_async(handler)(**request_.view_args)
  File "server.py", line 19, in home
    return await render_template("home.html")
  File "/home/runner/Tinsml/venv/lib/python3.8/site-packages/quart/templating.py", line 91, in render_template
    return await _render(template, context, current_app._get_current_object())  # type: ignore
  File "/home/runner/Tinsml/venv/lib/python3.8/site-packages/quart/templating.py", line 108, in _render
    rendered_template = await template.render_async(context)
  File "/home/runner/Tinsml/venv/lib/python3.8/site-packages/jinja2/environment.py", line 1324, in render_async
    return self.environment.handle_exception()
  File "/home/runner/Tinsml/venv/lib/python3.8/site-packages/jinja2/environment.py", line 936, in handle_exception
    raise rewrite_traceback_stack(source=source)
  File "/home/runner/Tinsml/venv/lib/python3.8/site-packages/jinja2/environment.py", line 1321, in <listcomp>
    [n async for n in self.root_render_func(ctx)]  # type: ignore
  File "/home/runner/Tinsml/templates/home.html", line 1, in top-level template code
    {% extends 'base.html' %}
  File "/home/runner/Tinsml/venv/lib/python3.8/site-packages/jinja2/environment.py", line 936, in handle_exception
    raise rewrite_traceback_stack(source=source)
  File "/home/runner/Tinsml/templates/base.html", line 213, in template
    {% block cpr %}
jinja2.exceptions.TemplateSyntaxError: Unexpected end of template. Jinja was looking for the following tags: 'endblock'. The innermost block that needs to be closed is 'block'.
Exception on request GET /
Traceback (most recent call last):
  File "/home/runner/Tinsml/venv/lib/python3.8/site-packages/quart/app.py", line 1489, in handle_request
    return await self.full_dispatch_request(request_context)
  File "/home/runner/Tinsml/venv/lib/python3.8/site-packages/quart/app.py", line 1514, in full_dispatch_request
    result = await self.handle_user_exception(error)
  File "/home/runner/Tinsml/venv/lib/python3.8/site-packages/quart/app.py", line 964, in handle_user_exception
    raise error
  File "/home/runner/Tinsml/venv/lib/python3.8/site-packages/quart/app.py", line 1512, in full_dispatch_request
    result = await self.dispatch_request(request_context)
  File "/home/runner/Tinsml/venv/lib/python3.8/site-packages/quart/app.py", line 1557, in dispatch_request
    return await self.ensure_async(handler)(**request_.view_args)
  File "server.py", line 19, in home
    return await render_template("home.html")
  File "/home/runner/Tinsml/venv/lib/python3.8/site-packages/quart/templating.py", line 91, in render_template
    return await _render(template, context, current_app._get_current_object())  # type: ignore
  File "/home/runner/Tinsml/venv/lib/python3.8/site-packages/quart/templating.py", line 108, in _render
    rendered_template = await template.render_async(context)
  File "/home/runner/Tinsml/venv/lib/python3.8/site-packages/jinja2/environment.py", line 1324, in render_async
    return self.environment.handle_exception()
  File "/home/runner/Tinsml/venv/lib/python3.8/site-packages/jinja2/environment.py", line 936, in handle_exception
    raise rewrite_traceback_stack(source=source)
  File "/home/runner/Tinsml/venv/lib/python3.8/site-packages/jinja2/environment.py", line 1321, in <listcomp>
    [n async for n in self.root_render_func(ctx)]  # type: ignore
  File "/home/runner/Tinsml/templates/home.html", line 1, in top-level template code
    {% extends 'base.html' %}
  File "/home/runner/Tinsml/venv/lib/python3.8/site-packages/jinja2/environment.py", line 936, in handle_exception
    raise rewrite_traceback_stack(source=source)
  File "/home/runner/Tinsml/templates/base.html", line 213, in template
    {% block cpr %}
jinja2.exceptions.TemplateSyntaxError: Unexpected end of template. Jinja was looking for the following tags: 'endblock'. The innermost block that needs to be closed is 'block'.
Exception on request GET /
Traceback (most recent call last):
  File "/home/runner/Tinsml/venv/lib/python3.8/site-packages/quart/app.py", line 1489, in handle_request
    return await self.full_dispatch_request(request_context)
  File "/home/runner/Tinsml/venv/lib/python3.8/site-packages/quart/app.py", line 1514, in full_dispatch_request
    result = await self.handle_user_exception(error)
  File "/home/runner/Tinsml/venv/lib/python3.8/site-packages/quart/app.py", line 964, in handle_user_exception
    raise error
  File "/home/runner/Tinsml/venv/lib/python3.8/site-packages/quart/app.py", line 1512, in full_dispatch_request
    result = await self.dispatch_request(request_context)
  File "/home/runner/Tinsml/venv/lib/python3.8/site-packages/quart/app.py", line 1557, in dispatch_request
    return await self.ensure_async(handler)(**request_.view_args)
  File "server.py", line 19, in home
    return await render_template("home.html")
  File "/home/runner/Tinsml/venv/lib/python3.8/site-packages/quart/templating.py", line 91, in render_template
    return await _render(template, context, current_app._get_current_object())  # type: ignore
  File "/home/runner/Tinsml/venv/lib/python3.8/site-packages/quart/templating.py", line 108, in _render
    rendered_template = await template.render_async(context)
  File "/home/runner/Tinsml/venv/lib/python3.8/site-packages/jinja2/environment.py", line 1324, in render_async
    return self.environment.handle_exception()
  File "/home/runner/Tinsml/venv/lib/python3.8/site-packages/jinja2/environment.py", line 936, in handle_exception
    raise rewrite_traceback_stack(source=source)
  File "/home/runner/Tinsml/venv/lib/python3.8/site-packages/jinja2/environment.py", line 1321, in <listcomp>
    [n async for n in self.root_render_func(ctx)]  # type: ignore
  File "/home/runner/Tinsml/templates/home.html", line 1, in top-level template code
    {% extends 'base.html' %}
  File "/home/runner/Tinsml/venv/lib/python3.8/site-packages/jinja2/environment.py", line 936, in handle_exception
    raise rewrite_traceback_stack(source=source)
  File "/home/runner/Tinsml/templates/base.html", line 213, in template
    {% block cpr %}
jinja2.exceptions.TemplateSyntaxError: Unexpected end of template. Jinja was looking for the following tags: 'endblock'. The innermost block that needs to be closed is 'block'.
Exception on request GET /
Traceback (most recent call last):
  File "/home/runner/Tinsml/venv/lib/python3.8/site-packages/quart/app.py", line 1489, in handle_request
    return await self.full_dispatch_request(request_context)
  File "/home/runner/Tinsml/venv/lib/python3.8/site-packages/quart/app.py", line 1514, in full_dispatch_request
    result = await self.handle_user_exception(error)
  File "/home/runner/Tinsml/venv/lib/python3.8/site-packages/quart/app.py", line 964, in handle_user_exception
    raise error
  File "/home/runner/Tinsml/venv/lib/python3.8/site-packages/quart/app.py", line 1512, in full_dispatch_request
    result = await self.dispatch_request(request_context)
  File "/home/runner/Tinsml/venv/lib/python3.8/site-packages/quart/app.py", line 1557, in dispatch_request
    return await self.ensure_async(handler)(**request_.view_args)
  File "server.py", line 19, in home
    return await render_template("home.html")
  File "/home/runner/Tinsml/venv/lib/python3.8/site-packages/quart/templating.py", line 91, in render_template
    return await _render(template, context, current_app._get_current_object())  # type: ignore
  File "/home/runner/Tinsml/venv/lib/python3.8/site-packages/quart/templating.py", line 108, in _render
    rendered_template = await template.render_async(context)
  File "/home/runner/Tinsml/venv/lib/python3.8/site-packages/jinja2/environment.py", line 1324, in render_async
    return self.environment.handle_exception()
  File "/home/runner/Tinsml/venv/lib/python3.8/site-packages/jinja2/environment.py", line 936, in handle_exception
    raise rewrite_traceback_stack(source=source)
  File "/home/runner/Tinsml/venv/lib/python3.8/site-packages/jinja2/environment.py", line 1321, in <listcomp>
    [n async for n in self.root_render_func(ctx)]  # type: ignore
  File "/home/runner/Tinsml/templates/home.html", line 1, in top-level template code
    {% extends 'base.html' %}
  File "/home/runner/Tinsml/templates/base.html", line 284, in top-level template code
    <a class="navbar-item" href="{{url_for('status_redirect')}}">
  File "/home/runner/Tinsml/venv/lib/python3.8/site-packages/quart/helpers.py", line 224, in url_for
    return app_context.app.handle_url_build_error(error, endpoint, values)
  File "/home/runner/Tinsml/venv/lib/python3.8/site-packages/quart/app.py", line 894, in handle_url_build_error
    raise error
  File "/home/runner/Tinsml/venv/lib/python3.8/site-packages/quart/helpers.py", line 222, in url_for
    url = url_adapter.build(endpoint, values, method=_method, force_external=_external)
  File "/home/runner/Tinsml/venv/lib/python3.8/site-packages/werkzeug/routing.py", line 2305, in build
    raise BuildError(endpoint, values, method, self)
werkzeug.routing.BuildError: Could not build url for endpoint 'status_redirect'. Did you mean 'status' instead?
Exception on request GET /
Traceback (most recent call last):
  File "/home/runner/Tinsml/venv/lib/python3.8/site-packages/quart/app.py", line 1489, in handle_request
    return await self.full_dispatch_request(request_context)
  File "/home/runner/Tinsml/venv/lib/python3.8/site-packages/quart/app.py", line 1514, in full_dispatch_request
    result = await self.handle_user_exception(error)
  File "/home/runner/Tinsml/venv/lib/python3.8/site-packages/quart/app.py", line 964, in handle_user_exception
    raise error
  File "/home/runner/Tinsml/venv/lib/python3.8/site-packages/quart/app.py", line 1512, in full_dispatch_request
    result = await self.dispatch_request(request_context)
  File "/home/runner/Tinsml/venv/lib/python3.8/site-packages/quart/app.py", line 1557, in dispatch_request
    return await self.ensure_async(handler)(**request_.view_args)
  File "server.py", line 19, in home
    return await render_template("home.html")
  File "/home/runner/Tinsml/venv/lib/python3.8/site-packages/quart/templating.py", line 91, in render_template
    return await _render(template, context, current_app._get_current_object())  # type: ignore
  File "/home/runner/Tinsml/venv/lib/python3.8/site-packages/quart/templating.py", line 108, in _render
    rendered_template = await template.render_async(context)
  File "/home/runner/Tinsml/venv/lib/python3.8/site-packages/jinja2/environment.py", line 1324, in render_async
    return self.environment.handle_exception()
  File "/home/runner/Tinsml/venv/lib/python3.8/site-packages/jinja2/environment.py", line 936, in handle_exception
    raise rewrite_traceback_stack(source=source)
  File "/home/runner/Tinsml/venv/lib/python3.8/site-packages/jinja2/environment.py", line 1321, in <listcomp>
    [n async for n in self.root_render_func(ctx)]  # type: ignore
  File "/home/runner/Tinsml/templates/home.html", line 1, in top-level template code
    {% extends 'base.html' %}
  File "/home/runner/Tinsml/templates/base.html", line 284, in top-level template code
    <a class="navbar-item" href="{{url_for('status_redirect')}}">
  File "/home/runner/Tinsml/venv/lib/python3.8/site-packages/quart/helpers.py", line 224, in url_for
    return app_context.app.handle_url_build_error(error, endpoint, values)
  File "/home/runner/Tinsml/venv/lib/python3.8/site-packages/quart/app.py", line 894, in handle_url_build_error
    raise error
  File "/home/runner/Tinsml/venv/lib/python3.8/site-packages/quart/helpers.py", line 222, in url_for
    url = url_adapter.build(endpoint, values, method=_method, force_external=_external)
  File "/home/runner/Tinsml/venv/lib/python3.8/site-packages/werkzeug/routing.py", line 2305, in build
    raise BuildError(endpoint, values, method, self)
werkzeug.routing.BuildError: Could not build url for endpoint 'status_redirect'. Did you mean 'status' instead?
Exception on request GET /seepagesource/code/madebytin
Traceback (most recent call last):
  File "/home/runner/Tinsml/venv/lib/python3.8/site-packages/quart/app.py", line 1489, in handle_request
    return await self.full_dispatch_request(request_context)
  File "/home/runner/Tinsml/venv/lib/python3.8/site-packages/quart/app.py", line 1514, in full_dispatch_request
    result = await self.handle_user_exception(error)
  File "/home/runner/Tinsml/venv/lib/python3.8/site-packages/quart/app.py", line 964, in handle_user_exception
    raise error
  File "/home/runner/Tinsml/venv/lib/python3.8/site-packages/quart/app.py", line 1512, in full_dispatch_request
    result = await self.dispatch_request(request_context)
  File "/home/runner/Tinsml/venv/lib/python3.8/site-packages/quart/app.py", line 1557, in dispatch_request
    return await self.ensure_async(handler)(**request_.view_args)
TypeError: sps_c() got an unexpected keyword argument 'secret'
Exception on request GET /seepagesource/code/madebytin
Traceback (most recent call last):
  File "/home/runner/Tinsml/venv/lib/python3.8/site-packages/quart/app.py", line 1489, in handle_request
    return await self.full_dispatch_request(request_context)
  File "/home/runner/Tinsml/venv/lib/python3.8/site-packages/quart/app.py", line 1514, in full_dispatch_request
    result = await self.handle_user_exception(error)
  File "/home/runner/Tinsml/venv/lib/python3.8/site-packages/quart/app.py", line 964, in handle_user_exception
    raise error
  File "/home/runner/Tinsml/venv/lib/python3.8/site-packages/quart/app.py", line 1512, in full_dispatch_request
    result = await self.dispatch_request(request_context)
  File "/home/runner/Tinsml/venv/lib/python3.8/site-packages/quart/app.py", line 1557, in dispatch_request
    return await self.ensure_async(handler)(**request_.view_args)
TypeError: sps_c() got an unexpected keyword argument 'secret'
Exception on request GET /seepagesource/code/madebytin
Traceback (most recent call last):
  File "/home/runner/Tinsml/venv/lib/python3.8/site-packages/quart/app.py", line 1489, in handle_request
    return await self.full_dispatch_request(request_context)
  File "/home/runner/Tinsml/venv/lib/python3.8/site-packages/quart/app.py", line 1514, in full_dispatch_request
    result = await self.handle_user_exception(error)
  File "/home/runner/Tinsml/venv/lib/python3.8/site-packages/quart/app.py", line 964, in handle_user_exception
    raise error
  File "/home/runner/Tinsml/venv/lib/python3.8/site-packages/quart/app.py", line 1512, in full_dispatch_request
    result = await self.dispatch_request(request_context)
  File "/home/runner/Tinsml/venv/lib/python3.8/site-packages/quart/app.py", line 1557, in dispatch_request
    return await self.ensure_async(handler)(**request_.view_args)
TypeError: sps_c() got an unexpected keyword argument 'secret'
Exception on request GET /seepagesource/code/madebytin
Traceback (most recent call last):
  File "/home/runner/Tinsml/venv/lib/python3.8/site-packages/quart/app.py", line 1489, in handle_request
    return await self.full_dispatch_request(request_context)
  File "/home/runner/Tinsml/venv/lib/python3.8/site-packages/quart/app.py", line 1514, in full_dispatch_request
    result = await self.handle_user_exception(error)
  File "/home/runner/Tinsml/venv/lib/python3.8/site-packages/quart/app.py", line 964, in handle_user_exception
    raise error
  File "/home/runner/Tinsml/venv/lib/python3.8/site-packages/quart/app.py", line 1512, in full_dispatch_request
    result = await self.dispatch_request(request_context)
  File "/home/runner/Tinsml/venv/lib/python3.8/site-packages/quart/app.py", line 1557, in dispatch_request
    return await self.ensure_async(handler)(**request_.view_args)
TypeError: sps_c() got an unexpected keyword argument 'secret'
Exception on request GET /seepagesource/code/madebytin
Traceback (most recent call last):
  File "/home/runner/Tinsml/venv/lib/python3.8/site-packages/quart/app.py", line 1489, in handle_request
    return await self.full_dispatch_request(request_context)
  File "/home/runner/Tinsml/venv/lib/python3.8/site-packages/quart/app.py", line 1514, in full_dispatch_request
    result = await self.handle_user_exception(error)
  File "/home/runner/Tinsml/venv/lib/python3.8/site-packages/quart/app.py", line 964, in handle_user_exception
    raise error
  File "/home/runner/Tinsml/venv/lib/python3.8/site-packages/quart/app.py", line 1512, in full_dispatch_request
    result = await self.dispatch_request(request_context)
  File "/home/runner/Tinsml/venv/lib/python3.8/site-packages/quart/app.py", line 1557, in dispatch_request
    return await self.ensure_async(handler)(**request_.view_args)
TypeError: sps_c() got an unexpected keyword argument 'secret'
Exception on request GET /seepagesource/code/madebytin
Traceback (most recent call last):
  File "/home/runner/Tinsml/venv/lib/python3.8/site-packages/quart/app.py", line 1489, in handle_request
    return await self.full_dispatch_request(request_context)
  File "/home/runner/Tinsml/venv/lib/python3.8/site-packages/quart/app.py", line 1514, in full_dispatch_request
    result = await self.handle_user_exception(error)
  File "/home/runner/Tinsml/venv/lib/python3.8/site-packages/quart/app.py", line 964, in handle_user_exception
    raise error
  File "/home/runner/Tinsml/venv/lib/python3.8/site-packages/quart/app.py", line 1512, in full_dispatch_request
    result = await self.dispatch_request(request_context)
  File "/home/runner/Tinsml/venv/lib/python3.8/site-packages/quart/app.py", line 1557, in dispatch_request
    return await self.ensure_async(handler)(**request_.view_args)
TypeError: sps_c() got an unexpected keyword argument 'secret'
Exception on request GET /seepagesource/code/madebytin
Traceback (most recent call last):
  File "/home/runner/Tinsml/venv/lib/python3.8/site-packages/quart/app.py", line 1489, in handle_request
    return await self.full_dispatch_request(request_context)
  File "/home/runner/Tinsml/venv/lib/python3.8/site-packages/quart/app.py", line 1514, in full_dispatch_request
    result = await self.handle_user_exception(error)
  File "/home/runner/Tinsml/venv/lib/python3.8/site-packages/quart/app.py", line 964, in handle_user_exception
    raise error
  File "/home/runner/Tinsml/venv/lib/python3.8/site-packages/quart/app.py", line 1512, in full_dispatch_request
    result = await self.dispatch_request(request_context)
  File "/home/runner/Tinsml/venv/lib/python3.8/site-packages/quart/app.py", line 1557, in dispatch_request
    return await self.ensure_async(handler)(**request_.view_args)
TypeError: sps_c() got an unexpected keyword argument 'secret'
Exception on request GET /seepagesource/code/madebytin
Traceback (most recent call last):
  File "/home/runner/Tinsml/venv/lib/python3.8/site-packages/quart/app.py", line 1489, in handle_request
    return await self.full_dispatch_request(request_context)
  File "/home/runner/Tinsml/venv/lib/python3.8/site-packages/quart/app.py", line 1514, in full_dispatch_request
    result = await self.handle_user_exception(error)
  File "/home/runner/Tinsml/venv/lib/python3.8/site-packages/quart/app.py", line 964, in handle_user_exception
    raise error
  File "/home/runner/Tinsml/venv/lib/python3.8/site-packages/quart/app.py", line 1512, in full_dispatch_request
    result = await self.dispatch_request(request_context)
  File "/home/runner/Tinsml/venv/lib/python3.8/site-packages/quart/app.py", line 1557, in dispatch_request
    return await self.ensure_async(handler)(**request_.view_args)
TypeError: sps_c() got an unexpected keyword argument 'secret'
Exception on request GET /
Traceback (most recent call last):
  File "/home/runner/Tinsml/venv/lib/python3.8/site-packages/quart/app.py", line 1489, in handle_request
    return await self.full_dispatch_request(request_context)
  File "/home/runner/Tinsml/venv/lib/python3.8/site-packages/quart/app.py", line 1514, in full_dispatch_request
    result = await self.handle_user_exception(error)
  File "/home/runner/Tinsml/venv/lib/python3.8/site-packages/quart/app.py", line 964, in handle_user_exception
    raise error
  File "/home/runner/Tinsml/venv/lib/python3.8/site-packages/quart/app.py", line 1512, in full_dispatch_request
    result = await self.dispatch_request(request_context)
  File "/home/runner/Tinsml/venv/lib/python3.8/site-packages/quart/app.py", line 1557, in dispatch_request
    return await self.ensure_async(handler)(**request_.view_args)
  File "server.py", line 18, in home
    return await render_template("home.html")
  File "/home/runner/Tinsml/venv/lib/python3.8/site-packages/quart/templating.py", line 91, in render_template
    return await _render(template, context, current_app._get_current_object())  # type: ignore
  File "/home/runner/Tinsml/venv/lib/python3.8/site-packages/quart/templating.py", line 108, in _render
    rendered_template = await template.render_async(context)
  File "/home/runner/Tinsml/venv/lib/python3.8/site-packages/jinja2/environment.py", line 1324, in render_async
    return self.environment.handle_exception()
  File "/home/runner/Tinsml/venv/lib/python3.8/site-packages/jinja2/environment.py", line 936, in handle_exception
    raise rewrite_traceback_stack(source=source)
  File "/home/runner/Tinsml/venv/lib/python3.8/site-packages/jinja2/environment.py", line 1321, in <listcomp>
    [n async for n in self.root_render_func(ctx)]  # type: ignore
  File "/home/runner/Tinsml/templates/home.html", line 1, in top-level template code
    {% extends 'base.html' %}
  File "/home/runner/Tinsml/templates/base.html", line 68, in top-level template code
    <title>{% block title required %} {% endblock %} - {{ original_url.rpartition("//")[-1].partition("/")[0] }}</title>
  File "/home/runner/Tinsml/venv/lib/python3.8/site-packages/jinja2/environment.py", line 485, in getattr
    return getattr(obj, attribute)
jinja2.exceptions.UndefinedError: 'original_url' is undefined
Exception on request GET /
Traceback (most recent call last):
  File "/home/runner/Tinsml/venv/lib/python3.8/site-packages/quart/app.py", line 1489, in handle_request
    return await self.full_dispatch_request(request_context)
  File "/home/runner/Tinsml/venv/lib/python3.8/site-packages/quart/app.py", line 1514, in full_dispatch_request
    result = await self.handle_user_exception(error)
  File "/home/runner/Tinsml/venv/lib/python3.8/site-packages/quart/app.py", line 964, in handle_user_exception
    raise error
  File "/home/runner/Tinsml/venv/lib/python3.8/site-packages/quart/app.py", line 1512, in full_dispatch_request
    result = await self.dispatch_request(request_context)
  File "/home/runner/Tinsml/venv/lib/python3.8/site-packages/quart/app.py", line 1557, in dispatch_request
    return await self.ensure_async(handler)(**request_.view_args)
  File "server.py", line 18, in home
    return await render_template("home.html")
  File "/home/runner/Tinsml/venv/lib/python3.8/site-packages/quart/templating.py", line 91, in render_template
    return await _render(template, context, current_app._get_current_object())  # type: ignore
  File "/home/runner/Tinsml/venv/lib/python3.8/site-packages/quart/templating.py", line 108, in _render
    rendered_template = await template.render_async(context)
  File "/home/runner/Tinsml/venv/lib/python3.8/site-packages/jinja2/environment.py", line 1324, in render_async
    return self.environment.handle_exception()
  File "/home/runner/Tinsml/venv/lib/python3.8/site-packages/jinja2/environment.py", line 936, in handle_exception
    raise rewrite_traceback_stack(source=source)
  File "/home/runner/Tinsml/venv/lib/python3.8/site-packages/jinja2/environment.py", line 1321, in <listcomp>
    [n async for n in self.root_render_func(ctx)]  # type: ignore
  File "/home/runner/Tinsml/templates/home.html", line 1, in top-level template code
    {% extends 'base.html' %}
  File "/home/runner/Tinsml/templates/base.html", line 68, in top-level template code
    <title>{% block title required %} {% endblock %} - {{ original_url.rpartition("//")[-1].partition("/")[0] }}</title>
  File "/home/runner/Tinsml/venv/lib/python3.8/site-packages/jinja2/environment.py", line 485, in getattr
    return getattr(obj, attribute)
jinja2.exceptions.UndefinedError: 'original_url' is undefined
Exception on request GET /
Traceback (most recent call last):
  File "/home/runner/Tinsml/venv/lib/python3.8/site-packages/quart/app.py", line 1489, in handle_request
    return await self.full_dispatch_request(request_context)
  File "/home/runner/Tinsml/venv/lib/python3.8/site-packages/quart/app.py", line 1514, in full_dispatch_request
    result = await self.handle_user_exception(error)
  File "/home/runner/Tinsml/venv/lib/python3.8/site-packages/quart/app.py", line 964, in handle_user_exception
    raise error
  File "/home/runner/Tinsml/venv/lib/python3.8/site-packages/quart/app.py", line 1512, in full_dispatch_request
    result = await self.dispatch_request(request_context)
  File "/home/runner/Tinsml/venv/lib/python3.8/site-packages/quart/app.py", line 1557, in dispatch_request
    return await self.ensure_async(handler)(**request_.view_args)
  File "server.py", line 18, in home
    return await render_template("home.html")
  File "/home/runner/Tinsml/venv/lib/python3.8/site-packages/quart/templating.py", line 91, in render_template
    return await _render(template, context, current_app._get_current_object())  # type: ignore
  File "/home/runner/Tinsml/venv/lib/python3.8/site-packages/quart/templating.py", line 108, in _render
    rendered_template = await template.render_async(context)
  File "/home/runner/Tinsml/venv/lib/python3.8/site-packages/jinja2/environment.py", line 1324, in render_async
    return self.environment.handle_exception()
  File "/home/runner/Tinsml/venv/lib/python3.8/site-packages/jinja2/environment.py", line 936, in handle_exception
    raise rewrite_traceback_stack(source=source)
  File "/home/runner/Tinsml/venv/lib/python3.8/site-packages/jinja2/environment.py", line 1321, in <listcomp>
    [n async for n in self.root_render_func(ctx)]  # type: ignore
  File "/home/runner/Tinsml/templates/home.html", line 1, in top-level template code
    {% extends 'base.html' %}
  File "/home/runner/Tinsml/templates/base.html", line 68, in top-level template code
    <title>{% block title required %} {% endblock %} - {{ original_url.rpartition("//")[-1].partition("/")[0] }}</title>
  File "/home/runner/Tinsml/venv/lib/python3.8/site-packages/jinja2/environment.py", line 485, in getattr
    return getattr(obj, attribute)
jinja2.exceptions.UndefinedError: 'original_url' is undefined
Exception on request GET /
Traceback (most recent call last):
  File "/home/runner/Tinsml/venv/lib/python3.8/site-packages/quart/app.py", line 1489, in handle_request
    return await self.full_dispatch_request(request_context)
  File "/home/runner/Tinsml/venv/lib/python3.8/site-packages/quart/app.py", line 1514, in full_dispatch_request
    result = await self.handle_user_exception(error)
  File "/home/runner/Tinsml/venv/lib/python3.8/site-packages/quart/app.py", line 964, in handle_user_exception
    raise error
  File "/home/runner/Tinsml/venv/lib/python3.8/site-packages/quart/app.py", line 1512, in full_dispatch_request
    result = await self.dispatch_request(request_context)
  File "/home/runner/Tinsml/venv/lib/python3.8/site-packages/quart/app.py", line 1557, in dispatch_request
    return await self.ensure_async(handler)(**request_.view_args)
  File "server.py", line 18, in home
    return await render_template("home.html")
  File "/home/runner/Tinsml/venv/lib/python3.8/site-packages/quart/templating.py", line 91, in render_template
    return await _render(template, context, current_app._get_current_object())  # type: ignore
  File "/home/runner/Tinsml/venv/lib/python3.8/site-packages/quart/templating.py", line 108, in _render
    rendered_template = await template.render_async(context)
  File "/home/runner/Tinsml/venv/lib/python3.8/site-packages/jinja2/environment.py", line 1324, in render_async
    return self.environment.handle_exception()
  File "/home/runner/Tinsml/venv/lib/python3.8/site-packages/jinja2/environment.py", line 936, in handle_exception
    raise rewrite_traceback_stack(source=source)
  File "/home/runner/Tinsml/venv/lib/python3.8/site-packages/jinja2/environment.py", line 1321, in <listcomp>
    [n async for n in self.root_render_func(ctx)]  # type: ignore
  File "/home/runner/Tinsml/templates/home.html", line 1, in top-level template code
    {% extends 'base.html' %}
  File "/home/runner/Tinsml/templates/base.html", line 68, in top-level template code
    <title>{% block title required %} {% endblock %} - {{ original_url.rpartition("//")[-1].partition("/")[0] }}</title>
  File "/home/runner/Tinsml/venv/lib/python3.8/site-packages/jinja2/environment.py", line 485, in getattr
    return getattr(obj, attribute)
jinja2.exceptions.UndefinedError: 'original_url' is undefined
Exception on request GET /
Traceback (most recent call last):
  File "/home/runner/Tinsml/venv/lib/python3.8/site-packages/quart/app.py", line 1489, in handle_request
    return await self.full_dispatch_request(request_context)
  File "/home/runner/Tinsml/venv/lib/python3.8/site-packages/quart/app.py", line 1514, in full_dispatch_request
    result = await self.handle_user_exception(error)
  File "/home/runner/Tinsml/venv/lib/python3.8/site-packages/quart/app.py", line 964, in handle_user_exception
    raise error
  File "/home/runner/Tinsml/venv/lib/python3.8/site-packages/quart/app.py", line 1512, in full_dispatch_request
    result = await self.dispatch_request(request_context)
  File "/home/runner/Tinsml/venv/lib/python3.8/site-packages/quart/app.py", line 1557, in dispatch_request
    return await self.ensure_async(handler)(**request_.view_args)
  File "server.py", line 18, in home
    return await render_template("home.html")
  File "/home/runner/Tinsml/venv/lib/python3.8/site-packages/quart/templating.py", line 91, in render_template
    return await _render(template, context, current_app._get_current_object())  # type: ignore
  File "/home/runner/Tinsml/venv/lib/python3.8/site-packages/quart/templating.py", line 108, in _render
    rendered_template = await template.render_async(context)
  File "/home/runner/Tinsml/venv/lib/python3.8/site-packages/jinja2/environment.py", line 1324, in render_async
    return self.environment.handle_exception()
  File "/home/runner/Tinsml/venv/lib/python3.8/site-packages/jinja2/environment.py", line 936, in handle_exception
    raise rewrite_traceback_stack(source=source)
  File "/home/runner/Tinsml/venv/lib/python3.8/site-packages/jinja2/environment.py", line 1321, in <listcomp>
    [n async for n in self.root_render_func(ctx)]  # type: ignore
  File "/home/runner/Tinsml/templates/home.html", line 1, in top-level template code
    {% extends 'base.html' %}
  File "/home/runner/Tinsml/templates/base.html", line 68, in top-level template code
    <title>{% block title required %} {% endblock %} - {{ original_url.rpartition("//")[-1].partition("/")[0] }}</title>
  File "/home/runner/Tinsml/venv/lib/python3.8/site-packages/jinja2/environment.py", line 485, in getattr
    return getattr(obj, attribute)
jinja2.exceptions.UndefinedError: 'original_url' is undefined
Exception on request GET /.git/config
Traceback (most recent call last):
  File "/home/runner/Tinsml/venv/lib/python3.8/site-packages/quart/app.py", line 1512, in full_dispatch_request
    result = await self.dispatch_request(request_context)
  File "/home/runner/Tinsml/venv/lib/python3.8/site-packages/quart/app.py", line 1551, in dispatch_request
    self.raise_routing_exception(request_)
  File "/home/runner/Tinsml/venv/lib/python3.8/site-packages/quart/app.py", line 1036, in raise_routing_exception
    raise request.routing_exception
  File "/home/runner/Tinsml/venv/lib/python3.8/site-packages/quart/ctx.py", line 68, in match_request
    ) = self.url_adapter.match(  # type: ignore
  File "/home/runner/Tinsml/venv/lib/python3.8/site-packages/werkzeug/routing.py", line 2047, in match
    raise NotFound()
werkzeug.exceptions.NotFound: 404 Not Found: The requested URL was not found on the server. If you entered the URL manually please check your spelling and try again.

During handling of the above exception, another exception occurred:

Traceback (most recent call last):
  File "/home/runner/Tinsml/venv/lib/python3.8/site-packages/quart/app.py", line 1489, in handle_request
    return await self.full_dispatch_request(request_context)
  File "/home/runner/Tinsml/venv/lib/python3.8/site-packages/quart/app.py", line 1514, in full_dispatch_request
    result = await self.handle_user_exception(error)
  File "/home/runner/Tinsml/venv/lib/python3.8/site-packages/quart/app.py", line 960, in handle_user_exception
    return await self.handle_http_exception(error)
  File "/home/runner/Tinsml/venv/lib/python3.8/site-packages/quart/app.py", line 938, in handle_http_exception
    return await self.ensure_async(handler)(error)
  File "server.py", line 55, in _404
    return await render_template("404.html")
  File "/home/runner/Tinsml/venv/lib/python3.8/site-packages/quart/templating.py", line 91, in render_template
    return await _render(template, context, current_app._get_current_object())  # type: ignore
  File "/home/runner/Tinsml/venv/lib/python3.8/site-packages/quart/templating.py", line 108, in _render
    rendered_template = await template.render_async(context)
  File "/home/runner/Tinsml/venv/lib/python3.8/site-packages/jinja2/environment.py", line 1324, in render_async
    return self.environment.handle_exception()
  File "/home/runner/Tinsml/venv/lib/python3.8/site-packages/jinja2/environment.py", line 936, in handle_exception
    raise rewrite_traceback_stack(source=source)
  File "/home/runner/Tinsml/venv/lib/python3.8/site-packages/jinja2/environment.py", line 1321, in <listcomp>
    [n async for n in self.root_render_func(ctx)]  # type: ignore
  File "/home/runner/Tinsml/templates/404.html", line 1, in top-level template code
    {% extends 'base.html' %}
  File "/home/runner/Tinsml/templates/base.html", line 68, in top-level template code
    <title>{% block title required %} {% endblock %} - {{ original_url.rpartition("//")[-1].partition("/")[0] }}</title>
  File "/home/runner/Tinsml/venv/lib/python3.8/site-packages/jinja2/environment.py", line 485, in getattr
    return getattr(obj, attribute)
jinja2.exceptions.UndefinedError: 'original_url' is undefined
Exception on request GET /
Traceback (most recent call last):
  File "/home/runner/Tinsml/venv/lib/python3.8/site-packages/quart/app.py", line 1489, in handle_request
    return await self.full_dispatch_request(request_context)
  File "/home/runner/Tinsml/venv/lib/python3.8/site-packages/quart/app.py", line 1514, in full_dispatch_request
    result = await self.handle_user_exception(error)
  File "/home/runner/Tinsml/venv/lib/python3.8/site-packages/quart/app.py", line 964, in handle_user_exception
    raise error
  File "/home/runner/Tinsml/venv/lib/python3.8/site-packages/quart/app.py", line 1512, in full_dispatch_request
    result = await self.dispatch_request(request_context)
  File "/home/runner/Tinsml/venv/lib/python3.8/site-packages/quart/app.py", line 1557, in dispatch_request
    return await self.ensure_async(handler)(**request_.view_args)
  File "server.py", line 18, in home
    return await render_template("home.html")
  File "/home/runner/Tinsml/venv/lib/python3.8/site-packages/quart/templating.py", line 91, in render_template
    return await _render(template, context, current_app._get_current_object())  # type: ignore
  File "/home/runner/Tinsml/venv/lib/python3.8/site-packages/quart/templating.py", line 108, in _render
    rendered_template = await template.render_async(context)
  File "/home/runner/Tinsml/venv/lib/python3.8/site-packages/jinja2/environment.py", line 1324, in render_async
    return self.environment.handle_exception()
  File "/home/runner/Tinsml/venv/lib/python3.8/site-packages/jinja2/environment.py", line 936, in handle_exception
    raise rewrite_traceback_stack(source=source)
  File "/home/runner/Tinsml/venv/lib/python3.8/site-packages/jinja2/environment.py", line 1321, in <listcomp>
    [n async for n in self.root_render_func(ctx)]  # type: ignore
  File "/home/runner/Tinsml/templates/home.html", line 1, in top-level template code
    {% extends 'base.html' %}
  File "/home/runner/Tinsml/templates/base.html", line 68, in top-level template code
    <title>{% block title required %} {% endblock %} - {{ original_url.rpartition("//")[-1].partition("/")[0] }}</title>
  File "/home/runner/Tinsml/venv/lib/python3.8/site-packages/jinja2/environment.py", line 485, in getattr
    return getattr(obj, attribute)
jinja2.exceptions.UndefinedError: 'original_url' is undefined
Exception on request HEAD /
Traceback (most recent call last):
  File "/home/runner/Tinsml/venv/lib/python3.8/site-packages/quart/app.py", line 1489, in handle_request
    return await self.full_dispatch_request(request_context)
  File "/home/runner/Tinsml/venv/lib/python3.8/site-packages/quart/app.py", line 1514, in full_dispatch_request
    result = await self.handle_user_exception(error)
  File "/home/runner/Tinsml/venv/lib/python3.8/site-packages/quart/app.py", line 964, in handle_user_exception
    raise error
  File "/home/runner/Tinsml/venv/lib/python3.8/site-packages/quart/app.py", line 1512, in full_dispatch_request
    result = await self.dispatch_request(request_context)
  File "/home/runner/Tinsml/venv/lib/python3.8/site-packages/quart/app.py", line 1557, in dispatch_request
    return await self.ensure_async(handler)(**request_.view_args)
  File "server.py", line 18, in home
    return await render_template("home.html")
  File "/home/runner/Tinsml/venv/lib/python3.8/site-packages/quart/templating.py", line 91, in render_template
    return await _render(template, context, current_app._get_current_object())  # type: ignore
  File "/home/runner/Tinsml/venv/lib/python3.8/site-packages/quart/templating.py", line 108, in _render
    rendered_template = await template.render_async(context)
  File "/home/runner/Tinsml/venv/lib/python3.8/site-packages/jinja2/environment.py", line 1324, in render_async
    return self.environment.handle_exception()
  File "/home/runner/Tinsml/venv/lib/python3.8/site-packages/jinja2/environment.py", line 936, in handle_exception
    raise rewrite_traceback_stack(source=source)
  File "/home/runner/Tinsml/venv/lib/python3.8/site-packages/jinja2/environment.py", line 1321, in <listcomp>
    [n async for n in self.root_render_func(ctx)]  # type: ignore
  File "/home/runner/Tinsml/templates/home.html", line 1, in top-level template code
    {% extends 'base.html' %}
  File "/home/runner/Tinsml/templates/base.html", line 68, in top-level template code
    <title>{% block title required %} {% endblock %} - {{ original_url.rpartition("//")[-1].partition("/")[0] }}</title>
  File "/home/runner/Tinsml/venv/lib/python3.8/site-packages/jinja2/environment.py", line 485, in getattr
    return getattr(obj, attribute)
jinja2.exceptions.UndefinedError: 'original_url' is undefined
Exception on request GET /
Traceback (most recent call last):
  File "/home/runner/Tinsml/venv/lib/python3.8/site-packages/quart/app.py", line 1489, in handle_request
    return await self.full_dispatch_request(request_context)
  File "/home/runner/Tinsml/venv/lib/python3.8/site-packages/quart/app.py", line 1514, in full_dispatch_request
    result = await self.handle_user_exception(error)
  File "/home/runner/Tinsml/venv/lib/python3.8/site-packages/quart/app.py", line 964, in handle_user_exception
    raise error
  File "/home/runner/Tinsml/venv/lib/python3.8/site-packages/quart/app.py", line 1512, in full_dispatch_request
    result = await self.dispatch_request(request_context)
  File "/home/runner/Tinsml/venv/lib/python3.8/site-packages/quart/app.py", line 1557, in dispatch_request
    return await self.ensure_async(handler)(**request_.view_args)
  File "server.py", line 18, in home
    return await render_template("home.html")
  File "/home/runner/Tinsml/venv/lib/python3.8/site-packages/quart/templating.py", line 91, in render_template
    return await _render(template, context, current_app._get_current_object())  # type: ignore
  File "/home/runner/Tinsml/venv/lib/python3.8/site-packages/quart/templating.py", line 108, in _render
    rendered_template = await template.render_async(context)
  File "/home/runner/Tinsml/venv/lib/python3.8/site-packages/jinja2/environment.py", line 1324, in render_async
    return self.environment.handle_exception()
  File "/home/runner/Tinsml/venv/lib/python3.8/site-packages/jinja2/environment.py", line 936, in handle_exception
    raise rewrite_traceback_stack(source=source)
  File "/home/runner/Tinsml/venv/lib/python3.8/site-packages/jinja2/environment.py", line 1321, in <listcomp>
    [n async for n in self.root_render_func(ctx)]  # type: ignore
  File "/home/runner/Tinsml/templates/home.html", line 1, in top-level template code
    {% extends 'base.html' %}
  File "/home/runner/Tinsml/templates/base.html", line 68, in top-level template code
    <title>{% block title required %} {% endblock %} - {{ original_url.rpartition("//")[-1].partition("/")[0] }}</title>
  File "/home/runner/Tinsml/venv/lib/python3.8/site-packages/jinja2/environment.py", line 485, in getattr
    return getattr(obj, attribute)
jinja2.exceptions.UndefinedError: 'original_url' is undefined
Exception on request GET /
Traceback (most recent call last):
  File "/home/runner/Tinsml/venv/lib/python3.8/site-packages/quart/app.py", line 1489, in handle_request
    return await self.full_dispatch_request(request_context)
  File "/home/runner/Tinsml/venv/lib/python3.8/site-packages/quart/app.py", line 1514, in full_dispatch_request
    result = await self.handle_user_exception(error)
  File "/home/runner/Tinsml/venv/lib/python3.8/site-packages/quart/app.py", line 964, in handle_user_exception
    raise error
  File "/home/runner/Tinsml/venv/lib/python3.8/site-packages/quart/app.py", line 1512, in full_dispatch_request
    result = await self.dispatch_request(request_context)
  File "/home/runner/Tinsml/venv/lib/python3.8/site-packages/quart/app.py", line 1557, in dispatch_request
    return await self.ensure_async(handler)(**request_.view_args)
  File "server.py", line 18, in home
    return await render_template("home.html")
  File "/home/runner/Tinsml/venv/lib/python3.8/site-packages/quart/templating.py", line 91, in render_template
    return await _render(template, context, current_app._get_current_object())  # type: ignore
  File "/home/runner/Tinsml/venv/lib/python3.8/site-packages/quart/templating.py", line 108, in _render
    rendered_template = await template.render_async(context)
  File "/home/runner/Tinsml/venv/lib/python3.8/site-packages/jinja2/environment.py", line 1324, in render_async
    return self.environment.handle_exception()
  File "/home/runner/Tinsml/venv/lib/python3.8/site-packages/jinja2/environment.py", line 936, in handle_exception
    raise rewrite_traceback_stack(source=source)
  File "/home/runner/Tinsml/venv/lib/python3.8/site-packages/jinja2/environment.py", line 1321, in <listcomp>
    [n async for n in self.root_render_func(ctx)]  # type: ignore
  File "/home/runner/Tinsml/templates/home.html", line 1, in top-level template code
    {% extends 'base.html' %}
  File "/home/runner/Tinsml/templates/base.html", line 68, in top-level template code
    <title>{% block title required %} {% endblock %} - {{ original_url.rpartition("//")[-1].partition("/")[0] }}</title>
  File "/home/runner/Tinsml/venv/lib/python3.8/site-packages/jinja2/environment.py", line 485, in getattr
    return getattr(obj, attribute)
jinja2.exceptions.UndefinedError: 'original_url' is undefined
Exception on request OPTIONS /*
Traceback (most recent call last):
  File "/home/runner/Tinsml/venv/lib/python3.8/site-packages/quart/app.py", line 1512, in full_dispatch_request
    result = await self.dispatch_request(request_context)
  File "/home/runner/Tinsml/venv/lib/python3.8/site-packages/quart/app.py", line 1551, in dispatch_request
    self.raise_routing_exception(request_)
  File "/home/runner/Tinsml/venv/lib/python3.8/site-packages/quart/app.py", line 1036, in raise_routing_exception
    raise request.routing_exception
  File "/home/runner/Tinsml/venv/lib/python3.8/site-packages/quart/ctx.py", line 68, in match_request
    ) = self.url_adapter.match(  # type: ignore
  File "/home/runner/Tinsml/venv/lib/python3.8/site-packages/werkzeug/routing.py", line 2047, in match
    raise NotFound()
werkzeug.exceptions.NotFound: 404 Not Found: The requested URL was not found on the server. If you entered the URL manually please check your spelling and try again.

During handling of the above exception, another exception occurred:

Traceback (most recent call last):
  File "/home/runner/Tinsml/venv/lib/python3.8/site-packages/quart/app.py", line 1489, in handle_request
    return await self.full_dispatch_request(request_context)
  File "/home/runner/Tinsml/venv/lib/python3.8/site-packages/quart/app.py", line 1514, in full_dispatch_request
    result = await self.handle_user_exception(error)
  File "/home/runner/Tinsml/venv/lib/python3.8/site-packages/quart/app.py", line 960, in handle_user_exception
    return await self.handle_http_exception(error)
  File "/home/runner/Tinsml/venv/lib/python3.8/site-packages/quart/app.py", line 938, in handle_http_exception
    return await self.ensure_async(handler)(error)
  File "server.py", line 55, in _404
    return await render_template("404.html")
  File "/home/runner/Tinsml/venv/lib/python3.8/site-packages/quart/templating.py", line 91, in render_template
    return await _render(template, context, current_app._get_current_object())  # type: ignore
  File "/home/runner/Tinsml/venv/lib/python3.8/site-packages/quart/templating.py", line 108, in _render
    rendered_template = await template.render_async(context)
  File "/home/runner/Tinsml/venv/lib/python3.8/site-packages/jinja2/environment.py", line 1324, in render_async
    return self.environment.handle_exception()
  File "/home/runner/Tinsml/venv/lib/python3.8/site-packages/jinja2/environment.py", line 936, in handle_exception
    raise rewrite_traceback_stack(source=source)
  File "/home/runner/Tinsml/venv/lib/python3.8/site-packages/jinja2/environment.py", line 1321, in <listcomp>
    [n async for n in self.root_render_func(ctx)]  # type: ignore
  File "/home/runner/Tinsml/templates/404.html", line 1, in top-level template code
    {% extends 'base.html' %}
  File "/home/runner/Tinsml/templates/base.html", line 68, in top-level template code
    <title>{% block title required %} {% endblock %} - {{ request.original_url.rpartition("//")[-1].partition("/")[0] }}</title>
  File "/home/runner/Tinsml/venv/lib/python3.8/site-packages/jinja2/environment.py", line 485, in getattr
    return getattr(obj, attribute)
jinja2.exceptions.UndefinedError: 'quart.wrappers.request.Request object' has no attribute 'original_url'
Exception on request GET /
Traceback (most recent call last):
  File "/home/runner/Tinsml/venv/lib/python3.8/site-packages/quart/app.py", line 1489, in handle_request
    return await self.full_dispatch_request(request_context)
  File "/home/runner/Tinsml/venv/lib/python3.8/site-packages/quart/app.py", line 1514, in full_dispatch_request
    result = await self.handle_user_exception(error)
  File "/home/runner/Tinsml/venv/lib/python3.8/site-packages/quart/app.py", line 964, in handle_user_exception
    raise error
  File "/home/runner/Tinsml/venv/lib/python3.8/site-packages/quart/app.py", line 1512, in full_dispatch_request
    result = await self.dispatch_request(request_context)
  File "/home/runner/Tinsml/venv/lib/python3.8/site-packages/quart/app.py", line 1557, in dispatch_request
    return await self.ensure_async(handler)(**request_.view_args)
  File "server.py", line 18, in home
    return await render_template("home.html")
  File "/home/runner/Tinsml/venv/lib/python3.8/site-packages/quart/templating.py", line 91, in render_template
    return await _render(template, context, current_app._get_current_object())  # type: ignore
  File "/home/runner/Tinsml/venv/lib/python3.8/site-packages/quart/templating.py", line 108, in _render
    rendered_template = await template.render_async(context)
  File "/home/runner/Tinsml/venv/lib/python3.8/site-packages/jinja2/environment.py", line 1324, in render_async
    return self.environment.handle_exception()
  File "/home/runner/Tinsml/venv/lib/python3.8/site-packages/jinja2/environment.py", line 936, in handle_exception
    raise rewrite_traceback_stack(source=source)
  File "/home/runner/Tinsml/venv/lib/python3.8/site-packages/jinja2/environment.py", line 1321, in <listcomp>
    [n async for n in self.root_render_func(ctx)]  # type: ignore
  File "/home/runner/Tinsml/templates/home.html", line 1, in top-level template code
    {% extends 'base.html' %}
  File "/home/runner/Tinsml/templates/base.html", line 68, in top-level template code
    <title>{% block title required %} {% endblock %} - {{ request.original_url.rpartition("//")[-1].partition("/")[0] }}</title>
  File "/home/runner/Tinsml/venv/lib/python3.8/site-packages/jinja2/environment.py", line 485, in getattr
    return getattr(obj, attribute)
jinja2.exceptions.UndefinedError: 'quart.wrappers.request.Request object' has no attribute 'original_url'
Exception on request GET /
Traceback (most recent call last):
  File "/home/runner/Tinsml/venv/lib/python3.8/site-packages/quart/app.py", line 1489, in handle_request
    return await self.full_dispatch_request(request_context)
  File "/home/runner/Tinsml/venv/lib/python3.8/site-packages/quart/app.py", line 1514, in full_dispatch_request
    result = await self.handle_user_exception(error)
  File "/home/runner/Tinsml/venv/lib/python3.8/site-packages/quart/app.py", line 964, in handle_user_exception
    raise error
  File "/home/runner/Tinsml/venv/lib/python3.8/site-packages/quart/app.py", line 1512, in full_dispatch_request
    result = await self.dispatch_request(request_context)
  File "/home/runner/Tinsml/venv/lib/python3.8/site-packages/quart/app.py", line 1557, in dispatch_request
    return await self.ensure_async(handler)(**request_.view_args)
  File "server.py", line 18, in home
    return await render_template("home.html")
  File "/home/runner/Tinsml/venv/lib/python3.8/site-packages/quart/templating.py", line 91, in render_template
    return await _render(template, context, current_app._get_current_object())  # type: ignore
  File "/home/runner/Tinsml/venv/lib/python3.8/site-packages/quart/templating.py", line 108, in _render
    rendered_template = await template.render_async(context)
  File "/home/runner/Tinsml/venv/lib/python3.8/site-packages/jinja2/environment.py", line 1324, in render_async
    return self.environment.handle_exception()
  File "/home/runner/Tinsml/venv/lib/python3.8/site-packages/jinja2/environment.py", line 936, in handle_exception
    raise rewrite_traceback_stack(source=source)
  File "/home/runner/Tinsml/venv/lib/python3.8/site-packages/jinja2/environment.py", line 1321, in <listcomp>
    [n async for n in self.root_render_func(ctx)]  # type: ignore
  File "/home/runner/Tinsml/templates/home.html", line 1, in top-level template code
    {% extends 'base.html' %}
  File "/home/runner/Tinsml/templates/base.html", line 68, in top-level template code
    <title>{% block title required %} {% endblock %} - {{ request.original_url.rpartition("//")[-1].partition("/")[0] }}</title>
  File "/home/runner/Tinsml/venv/lib/python3.8/site-packages/jinja2/environment.py", line 485, in getattr
    return getattr(obj, attribute)
jinja2.exceptions.UndefinedError: 'quart.wrappers.request.Request object' has no attribute 'original_url'
Exception on request GET /
Traceback (most recent call last):
  File "/home/runner/Tinsml/venv/lib/python3.8/site-packages/quart/app.py", line 1489, in handle_request
    return await self.full_dispatch_request(request_context)
  File "/home/runner/Tinsml/venv/lib/python3.8/site-packages/quart/app.py", line 1514, in full_dispatch_request
    result = await self.handle_user_exception(error)
  File "/home/runner/Tinsml/venv/lib/python3.8/site-packages/quart/app.py", line 964, in handle_user_exception
    raise error
  File "/home/runner/Tinsml/venv/lib/python3.8/site-packages/quart/app.py", line 1512, in full_dispatch_request
    result = await self.dispatch_request(request_context)
  File "/home/runner/Tinsml/venv/lib/python3.8/site-packages/quart/app.py", line 1557, in dispatch_request
    return await self.ensure_async(handler)(**request_.view_args)
  File "server.py", line 18, in home
    return await render_template("home.html")
  File "/home/runner/Tinsml/venv/lib/python3.8/site-packages/quart/templating.py", line 91, in render_template
    return await _render(template, context, current_app._get_current_object())  # type: ignore
  File "/home/runner/Tinsml/venv/lib/python3.8/site-packages/quart/templating.py", line 108, in _render
    rendered_template = await template.render_async(context)
  File "/home/runner/Tinsml/venv/lib/python3.8/site-packages/jinja2/environment.py", line 1324, in render_async
    return self.environment.handle_exception()
  File "/home/runner/Tinsml/venv/lib/python3.8/site-packages/jinja2/environment.py", line 936, in handle_exception
    raise rewrite_traceback_stack(source=source)
  File "/home/runner/Tinsml/venv/lib/python3.8/site-packages/jinja2/environment.py", line 1321, in <listcomp>
    [n async for n in self.root_render_func(ctx)]  # type: ignore
  File "/home/runner/Tinsml/templates/home.html", line 1, in top-level template code
    {% extends 'base.html' %}
  File "/home/runner/Tinsml/venv/lib/python3.8/site-packages/jinja2/environment.py", line 936, in handle_exception
    raise rewrite_traceback_stack(source=source)
  File "/home/runner/Tinsml/templates/base.html", line 277, in template
    {% block ext_head %} {% endblock %
jinja2.exceptions.TemplateSyntaxError: expected token 'end of statement block', got '%'
Exception on request GET /
Traceback (most recent call last):
  File "/home/runner/Tinsml/venv/lib/python3.8/site-packages/quart/app.py", line 1489, in handle_request
    return await self.full_dispatch_request(request_context)
  File "/home/runner/Tinsml/venv/lib/python3.8/site-packages/quart/app.py", line 1514, in full_dispatch_request
    result = await self.handle_user_exception(error)
  File "/home/runner/Tinsml/venv/lib/python3.8/site-packages/quart/app.py", line 964, in handle_user_exception
    raise error
  File "/home/runner/Tinsml/venv/lib/python3.8/site-packages/quart/app.py", line 1512, in full_dispatch_request
    result = await self.dispatch_request(request_context)
  File "/home/runner/Tinsml/venv/lib/python3.8/site-packages/quart/app.py", line 1557, in dispatch_request
    return await self.ensure_async(handler)(**request_.view_args)
  File "server.py", line 18, in home
    return await render_template("home.html")
  File "/home/runner/Tinsml/venv/lib/python3.8/site-packages/quart/templating.py", line 91, in render_template
    return await _render(template, context, current_app._get_current_object())  # type: ignore
  File "/home/runner/Tinsml/venv/lib/python3.8/site-packages/quart/templating.py", line 108, in _render
    rendered_template = await template.render_async(context)
  File "/home/runner/Tinsml/venv/lib/python3.8/site-packages/jinja2/environment.py", line 1324, in render_async
    return self.environment.handle_exception()
  File "/home/runner/Tinsml/venv/lib/python3.8/site-packages/jinja2/environment.py", line 936, in handle_exception
    raise rewrite_traceback_stack(source=source)
  File "/home/runner/Tinsml/venv/lib/python3.8/site-packages/jinja2/environment.py", line 1321, in <listcomp>
    [n async for n in self.root_render_func(ctx)]  # type: ignore
  File "/home/runner/Tinsml/templates/home.html", line 1, in top-level template code
    {% extends 'base.html' %}
  File "/home/runner/Tinsml/venv/lib/python3.8/site-packages/jinja2/environment.py", line 936, in handle_exception
    raise rewrite_traceback_stack(source=source)
  File "/home/runner/Tinsml/templates/base.html", line 277, in template
    {% block ext_head %} {% endblock %
jinja2.exceptions.TemplateSyntaxError: expected token 'end of statement block', got '%'
Exception on request GET /
Traceback (most recent call last):
  File "/home/runner/Tinsml/venv/lib/python3.8/site-packages/quart/app.py", line 1489, in handle_request
    return await self.full_dispatch_request(request_context)
  File "/home/runner/Tinsml/venv/lib/python3.8/site-packages/quart/app.py", line 1514, in full_dispatch_request
    result = await self.handle_user_exception(error)
  File "/home/runner/Tinsml/venv/lib/python3.8/site-packages/quart/app.py", line 964, in handle_user_exception
    raise error
  File "/home/runner/Tinsml/venv/lib/python3.8/site-packages/quart/app.py", line 1512, in full_dispatch_request
    result = await self.dispatch_request(request_context)
  File "/home/runner/Tinsml/venv/lib/python3.8/site-packages/quart/app.py", line 1557, in dispatch_request
    return await self.ensure_async(handler)(**request_.view_args)
  File "server.py", line 18, in home
    return await render_template("home.html")
  File "/home/runner/Tinsml/venv/lib/python3.8/site-packages/quart/templating.py", line 91, in render_template
    return await _render(template, context, current_app._get_current_object())  # type: ignore
  File "/home/runner/Tinsml/venv/lib/python3.8/site-packages/quart/templating.py", line 108, in _render
    rendered_template = await template.render_async(context)
  File "/home/runner/Tinsml/venv/lib/python3.8/site-packages/jinja2/environment.py", line 1324, in render_async
    return self.environment.handle_exception()
  File "/home/runner/Tinsml/venv/lib/python3.8/site-packages/jinja2/environment.py", line 936, in handle_exception
    raise rewrite_traceback_stack(source=source)
  File "/home/runner/Tinsml/venv/lib/python3.8/site-packages/jinja2/environment.py", line 1321, in <listcomp>
    [n async for n in self.root_render_func(ctx)]  # type: ignore
  File "/home/runner/Tinsml/templates/home.html", line 1, in top-level template code
    {% extends 'base.html' %}
  File "/home/runner/Tinsml/venv/lib/python3.8/site-packages/jinja2/environment.py", line 936, in handle_exception
    raise rewrite_traceback_stack(source=source)
  File "/home/runner/Tinsml/templates/base.html", line 275, in template
    {% block ext_head %} {% endblock %
jinja2.exceptions.TemplateSyntaxError: expected token 'end of statement block', got '%'
Exception on request GET /
Traceback (most recent call last):
  File "/home/runner/Tinsml/venv/lib/python3.8/site-packages/quart/app.py", line 1489, in handle_request
    return await self.full_dispatch_request(request_context)
  File "/home/runner/Tinsml/venv/lib/python3.8/site-packages/quart/app.py", line 1514, in full_dispatch_request
    result = await self.handle_user_exception(error)
  File "/home/runner/Tinsml/venv/lib/python3.8/site-packages/quart/app.py", line 964, in handle_user_exception
    raise error
  File "/home/runner/Tinsml/venv/lib/python3.8/site-packages/quart/app.py", line 1512, in full_dispatch_request
    result = await self.dispatch_request(request_context)
  File "/home/runner/Tinsml/venv/lib/python3.8/site-packages/quart/app.py", line 1557, in dispatch_request
    return await self.ensure_async(handler)(**request_.view_args)
  File "server.py", line 18, in home
    return await render_template("home.html")
  File "/home/runner/Tinsml/venv/lib/python3.8/site-packages/quart/templating.py", line 91, in render_template
    return await _render(template, context, current_app._get_current_object())  # type: ignore
  File "/home/runner/Tinsml/venv/lib/python3.8/site-packages/quart/templating.py", line 108, in _render
    rendered_template = await template.render_async(context)
  File "/home/runner/Tinsml/venv/lib/python3.8/site-packages/jinja2/environment.py", line 1324, in render_async
    return self.environment.handle_exception()
  File "/home/runner/Tinsml/venv/lib/python3.8/site-packages/jinja2/environment.py", line 936, in handle_exception
    raise rewrite_traceback_stack(source=source)
  File "/home/runner/Tinsml/venv/lib/python3.8/site-packages/jinja2/environment.py", line 1321, in <listcomp>
    [n async for n in self.root_render_func(ctx)]  # type: ignore
  File "/home/runner/Tinsml/templates/home.html", line 1, in top-level template code
    {% extends 'base.html' %}
  File "/home/runner/Tinsml/venv/lib/python3.8/site-packages/jinja2/environment.py", line 936, in handle_exception
    raise rewrite_traceback_stack(source=source)
  File "/home/runner/Tinsml/templates/base.html", line 275, in template
    {% block ext_head %} {% endblock %
jinja2.exceptions.TemplateSyntaxError: expected token 'end of statement block', got '%'
Exception on request GET /
Traceback (most recent call last):
  File "/home/runner/Tinsml/venv/lib/python3.8/site-packages/quart/app.py", line 1489, in handle_request
    return await self.full_dispatch_request(request_context)
  File "/home/runner/Tinsml/venv/lib/python3.8/site-packages/quart/app.py", line 1514, in full_dispatch_request
    result = await self.handle_user_exception(error)
  File "/home/runner/Tinsml/venv/lib/python3.8/site-packages/quart/app.py", line 964, in handle_user_exception
    raise error
  File "/home/runner/Tinsml/venv/lib/python3.8/site-packages/quart/app.py", line 1512, in full_dispatch_request
    result = await self.dispatch_request(request_context)
  File "/home/runner/Tinsml/venv/lib/python3.8/site-packages/quart/app.py", line 1557, in dispatch_request
    return await self.ensure_async(handler)(**request_.view_args)
  File "server.py", line 18, in home
    return await render_template("home.html")
  File "/home/runner/Tinsml/venv/lib/python3.8/site-packages/quart/templating.py", line 91, in render_template
    return await _render(template, context, current_app._get_current_object())  # type: ignore
  File "/home/runner/Tinsml/venv/lib/python3.8/site-packages/quart/templating.py", line 108, in _render
    rendered_template = await template.render_async(context)
  File "/home/runner/Tinsml/venv/lib/python3.8/site-packages/jinja2/environment.py", line 1324, in render_async
    return self.environment.handle_exception()
  File "/home/runner/Tinsml/venv/lib/python3.8/site-packages/jinja2/environment.py", line 936, in handle_exception
    raise rewrite_traceback_stack(source=source)
  File "/home/runner/Tinsml/venv/lib/python3.8/site-packages/jinja2/environment.py", line 1321, in <listcomp>
    [n async for n in self.root_render_func(ctx)]  # type: ignore
  File "/home/runner/Tinsml/templates/home.html", line 1, in top-level template code
    {% extends 'base.html' %}
  File "/home/runner/Tinsml/venv/lib/python3.8/site-packages/jinja2/environment.py", line 936, in handle_exception
    raise rewrite_traceback_stack(source=source)
  File "/home/runner/Tinsml/templates/base.html", line 275, in template
    {% block ext_head %} {% endblock %
jinja2.exceptions.TemplateSyntaxError: expected token 'end of statement block', got '%'
Exception on request GET /
Traceback (most recent call last):
  File "/home/runner/Tinsml/venv/lib/python3.8/site-packages/quart/app.py", line 1489, in handle_request
    return await self.full_dispatch_request(request_context)
  File "/home/runner/Tinsml/venv/lib/python3.8/site-packages/quart/app.py", line 1514, in full_dispatch_request
    result = await self.handle_user_exception(error)
  File "/home/runner/Tinsml/venv/lib/python3.8/site-packages/quart/app.py", line 964, in handle_user_exception
    raise error
  File "/home/runner/Tinsml/venv/lib/python3.8/site-packages/quart/app.py", line 1512, in full_dispatch_request
    result = await self.dispatch_request(request_context)
  File "/home/runner/Tinsml/venv/lib/python3.8/site-packages/quart/app.py", line 1557, in dispatch_request
    return await self.ensure_async(handler)(**request_.view_args)
  File "server.py", line 18, in home
    return await render_template("home.html")
  File "/home/runner/Tinsml/venv/lib/python3.8/site-packages/quart/templating.py", line 91, in render_template
    return await _render(template, context, current_app._get_current_object())  # type: ignore
  File "/home/runner/Tinsml/venv/lib/python3.8/site-packages/quart/templating.py", line 108, in _render
    rendered_template = await template.render_async(context)
  File "/home/runner/Tinsml/venv/lib/python3.8/site-packages/jinja2/environment.py", line 1324, in render_async
    return self.environment.handle_exception()
  File "/home/runner/Tinsml/venv/lib/python3.8/site-packages/jinja2/environment.py", line 936, in handle_exception
    raise rewrite_traceback_stack(source=source)
  File "/home/runner/Tinsml/venv/lib/python3.8/site-packages/jinja2/environment.py", line 1321, in <listcomp>
    [n async for n in self.root_render_func(ctx)]  # type: ignore
  File "/home/runner/Tinsml/templates/home.html", line 1, in top-level template code
    {% extends 'base.html' %}
  File "/home/runner/Tinsml/venv/lib/python3.8/site-packages/jinja2/environment.py", line 936, in handle_exception
    raise rewrite_traceback_stack(source=source)
  File "/home/runner/Tinsml/templates/base.html", line 275, in template
    {% block ext_head %} {% endblock %
jinja2.exceptions.TemplateSyntaxError: expected token 'end of statement block', got '%'
Exception on request GET /
Traceback (most recent call last):
  File "/home/runner/Tinsml/venv/lib/python3.8/site-packages/quart/app.py", line 1489, in handle_request
    return await self.full_dispatch_request(request_context)
  File "/home/runner/Tinsml/venv/lib/python3.8/site-packages/quart/app.py", line 1514, in full_dispatch_request
    result = await self.handle_user_exception(error)
  File "/home/runner/Tinsml/venv/lib/python3.8/site-packages/quart/app.py", line 964, in handle_user_exception
    raise error
  File "/home/runner/Tinsml/venv/lib/python3.8/site-packages/quart/app.py", line 1512, in full_dispatch_request
    result = await self.dispatch_request(request_context)
  File "/home/runner/Tinsml/venv/lib/python3.8/site-packages/quart/app.py", line 1557, in dispatch_request
    return await self.ensure_async(handler)(**request_.view_args)
  File "server.py", line 18, in home
    return await render_template("home.html")
  File "/home/runner/Tinsml/venv/lib/python3.8/site-packages/quart/templating.py", line 91, in render_template
    return await _render(template, context, current_app._get_current_object())  # type: ignore
  File "/home/runner/Tinsml/venv/lib/python3.8/site-packages/quart/templating.py", line 108, in _render
    rendered_template = await template.render_async(context)
  File "/home/runner/Tinsml/venv/lib/python3.8/site-packages/jinja2/environment.py", line 1324, in render_async
    return self.environment.handle_exception()
  File "/home/runner/Tinsml/venv/lib/python3.8/site-packages/jinja2/environment.py", line 936, in handle_exception
    raise rewrite_traceback_stack(source=source)
  File "/home/runner/Tinsml/venv/lib/python3.8/site-packages/jinja2/environment.py", line 1321, in <listcomp>
    [n async for n in self.root_render_func(ctx)]  # type: ignore
  File "/home/runner/Tinsml/templates/home.html", line 1, in top-level template code
    {% extends 'base.html' %}
  File "/home/runner/Tinsml/venv/lib/python3.8/site-packages/jinja2/environment.py", line 936, in handle_exception
    raise rewrite_traceback_stack(source=source)
  File "/home/runner/Tinsml/templates/base.html", line 275, in template
    {% block ext_head %} {% endblock %
jinja2.exceptions.TemplateSyntaxError: expected token 'end of statement block', got '%'
Exception on request GET /
Traceback (most recent call last):
  File "/home/runner/Tinsml/venv/lib/python3.8/site-packages/quart/app.py", line 1489, in handle_request
    return await self.full_dispatch_request(request_context)
  File "/home/runner/Tinsml/venv/lib/python3.8/site-packages/quart/app.py", line 1514, in full_dispatch_request
    result = await self.handle_user_exception(error)
  File "/home/runner/Tinsml/venv/lib/python3.8/site-packages/quart/app.py", line 964, in handle_user_exception
    raise error
  File "/home/runner/Tinsml/venv/lib/python3.8/site-packages/quart/app.py", line 1512, in full_dispatch_request
    result = await self.dispatch_request(request_context)
  File "/home/runner/Tinsml/venv/lib/python3.8/site-packages/quart/app.py", line 1557, in dispatch_request
    return await self.ensure_async(handler)(**request_.view_args)
  File "server.py", line 18, in home
    return await render_template("home.html")
  File "/home/runner/Tinsml/venv/lib/python3.8/site-packages/quart/templating.py", line 91, in render_template
    return await _render(template, context, current_app._get_current_object())  # type: ignore
  File "/home/runner/Tinsml/venv/lib/python3.8/site-packages/quart/templating.py", line 108, in _render
    rendered_template = await template.render_async(context)
  File "/home/runner/Tinsml/venv/lib/python3.8/site-packages/jinja2/environment.py", line 1324, in render_async
    return self.environment.handle_exception()
  File "/home/runner/Tinsml/venv/lib/python3.8/site-packages/jinja2/environment.py", line 936, in handle_exception
    raise rewrite_traceback_stack(source=source)
  File "/home/runner/Tinsml/venv/lib/python3.8/site-packages/jinja2/environment.py", line 1321, in <listcomp>
    [n async for n in self.root_render_func(ctx)]  # type: ignore
  File "/home/runner/Tinsml/templates/home.html", line 1, in top-level template code
    {% extends 'base.html' %}
  File "/home/runner/Tinsml/venv/lib/python3.8/site-packages/jinja2/environment.py", line 936, in handle_exception
    raise rewrite_traceback_stack(source=source)
  File "/home/runner/Tinsml/templates/base.html", line 275, in template
    {% block ext_head %} {% endblock %
jinja2.exceptions.TemplateSyntaxError: expected token 'end of statement block', got '%'
Exception on request GET /
Traceback (most recent call last):
  File "/home/runner/Tinsml/venv/lib/python3.8/site-packages/quart/app.py", line 1489, in handle_request
    return await self.full_dispatch_request(request_context)
  File "/home/runner/Tinsml/venv/lib/python3.8/site-packages/quart/app.py", line 1514, in full_dispatch_request
    result = await self.handle_user_exception(error)
  File "/home/runner/Tinsml/venv/lib/python3.8/site-packages/quart/app.py", line 964, in handle_user_exception
    raise error
  File "/home/runner/Tinsml/venv/lib/python3.8/site-packages/quart/app.py", line 1512, in full_dispatch_request
    result = await self.dispatch_request(request_context)
  File "/home/runner/Tinsml/venv/lib/python3.8/site-packages/quart/app.py", line 1557, in dispatch_request
    return await self.ensure_async(handler)(**request_.view_args)
  File "server.py", line 18, in home
    return await render_template("home.html")
  File "/home/runner/Tinsml/venv/lib/python3.8/site-packages/quart/templating.py", line 91, in render_template
    return await _render(template, context, current_app._get_current_object())  # type: ignore
  File "/home/runner/Tinsml/venv/lib/python3.8/site-packages/quart/templating.py", line 108, in _render
    rendered_template = await template.render_async(context)
  File "/home/runner/Tinsml/venv/lib/python3.8/site-packages/jinja2/environment.py", line 1324, in render_async
    return self.environment.handle_exception()
  File "/home/runner/Tinsml/venv/lib/python3.8/site-packages/jinja2/environment.py", line 936, in handle_exception
    raise rewrite_traceback_stack(source=source)
  File "/home/runner/Tinsml/venv/lib/python3.8/site-packages/jinja2/environment.py", line 1321, in <listcomp>
    [n async for n in self.root_render_func(ctx)]  # type: ignore
  File "/home/runner/Tinsml/templates/home.html", line 1, in top-level template code
    {% extends 'base.html' %}
  File "/home/runner/Tinsml/venv/lib/python3.8/site-packages/jinja2/environment.py", line 936, in handle_exception
    raise rewrite_traceback_stack(source=source)
  File "/home/runner/Tinsml/templates/base.html", line 275, in template
    {% block ext_head %} {% endblock %
jinja2.exceptions.TemplateSyntaxError: expected token 'end of statement block', got '%'
Exception on request GET /
Traceback (most recent call last):
  File "/home/runner/Tinsml/venv/lib/python3.8/site-packages/quart/app.py", line 1489, in handle_request
    return await self.full_dispatch_request(request_context)
  File "/home/runner/Tinsml/venv/lib/python3.8/site-packages/quart/app.py", line 1514, in full_dispatch_request
    result = await self.handle_user_exception(error)
  File "/home/runner/Tinsml/venv/lib/python3.8/site-packages/quart/app.py", line 964, in handle_user_exception
    raise error
  File "/home/runner/Tinsml/venv/lib/python3.8/site-packages/quart/app.py", line 1512, in full_dispatch_request
    result = await self.dispatch_request(request_context)
  File "/home/runner/Tinsml/venv/lib/python3.8/site-packages/quart/app.py", line 1557, in dispatch_request
    return await self.ensure_async(handler)(**request_.view_args)
  File "server.py", line 18, in home
    return await render_template("home.html")
  File "/home/runner/Tinsml/venv/lib/python3.8/site-packages/quart/templating.py", line 91, in render_template
    return await _render(template, context, current_app._get_current_object())  # type: ignore
  File "/home/runner/Tinsml/venv/lib/python3.8/site-packages/quart/templating.py", line 108, in _render
    rendered_template = await template.render_async(context)
  File "/home/runner/Tinsml/venv/lib/python3.8/site-packages/jinja2/environment.py", line 1324, in render_async
    return self.environment.handle_exception()
  File "/home/runner/Tinsml/venv/lib/python3.8/site-packages/jinja2/environment.py", line 936, in handle_exception
    raise rewrite_traceback_stack(source=source)
  File "/home/runner/Tinsml/venv/lib/python3.8/site-packages/jinja2/environment.py", line 1321, in <listcomp>
    [n async for n in self.root_render_func(ctx)]  # type: ignore
  File "/home/runner/Tinsml/templates/home.html", line 1, in top-level template code
    {% extends 'base.html' %}
  File "/home/runner/Tinsml/venv/lib/python3.8/site-packages/jinja2/environment.py", line 936, in handle_exception
    raise rewrite_traceback_stack(source=source)
  File "/home/runner/Tinsml/templates/base.html", line 275, in template
    {% block ext_head %} {% endblock %
jinja2.exceptions.TemplateSyntaxError: expected token 'end of statement block', got '%'
Exception on request GET /
Traceback (most recent call last):
  File "/home/runner/Tinsml/venv/lib/python3.8/site-packages/quart/app.py", line 1489, in handle_request
    return await self.full_dispatch_request(request_context)
  File "/home/runner/Tinsml/venv/lib/python3.8/site-packages/quart/app.py", line 1514, in full_dispatch_request
    result = await self.handle_user_exception(error)
  File "/home/runner/Tinsml/venv/lib/python3.8/site-packages/quart/app.py", line 964, in handle_user_exception
    raise error
  File "/home/runner/Tinsml/venv/lib/python3.8/site-packages/quart/app.py", line 1512, in full_dispatch_request
    result = await self.dispatch_request(request_context)
  File "/home/runner/Tinsml/venv/lib/python3.8/site-packages/quart/app.py", line 1557, in dispatch_request
    return await self.ensure_async(handler)(**request_.view_args)
  File "server.py", line 18, in home
    return await render_template("home.html")
  File "/home/runner/Tinsml/venv/lib/python3.8/site-packages/quart/templating.py", line 91, in render_template
    return await _render(template, context, current_app._get_current_object())  # type: ignore
  File "/home/runner/Tinsml/venv/lib/python3.8/site-packages/quart/templating.py", line 108, in _render
    rendered_template = await template.render_async(context)
  File "/home/runner/Tinsml/venv/lib/python3.8/site-packages/jinja2/environment.py", line 1324, in render_async
    return self.environment.handle_exception()
  File "/home/runner/Tinsml/venv/lib/python3.8/site-packages/jinja2/environment.py", line 936, in handle_exception
    raise rewrite_traceback_stack(source=source)
  File "/home/runner/Tinsml/venv/lib/python3.8/site-packages/jinja2/environment.py", line 1321, in <listcomp>
    [n async for n in self.root_render_func(ctx)]  # type: ignore
  File "/home/runner/Tinsml/templates/home.html", line 1, in top-level template code
    {% extends 'base.html' %}
  File "/home/runner/Tinsml/venv/lib/python3.8/site-packages/jinja2/environment.py", line 936, in handle_exception
    raise rewrite_traceback_stack(source=source)
  File "/home/runner/Tinsml/templates/base.html", line 275, in template
    {% block ext_head %} {% endblock %
jinja2.exceptions.TemplateSyntaxError: expected token 'end of statement block', got '%'
Exception on request GET /
Traceback (most recent call last):
  File "/home/runner/Tinsml/venv/lib/python3.8/site-packages/quart/app.py", line 1489, in handle_request
    return await self.full_dispatch_request(request_context)
  File "/home/runner/Tinsml/venv/lib/python3.8/site-packages/quart/app.py", line 1514, in full_dispatch_request
    result = await self.handle_user_exception(error)
  File "/home/runner/Tinsml/venv/lib/python3.8/site-packages/quart/app.py", line 964, in handle_user_exception
    raise error
  File "/home/runner/Tinsml/venv/lib/python3.8/site-packages/quart/app.py", line 1512, in full_dispatch_request
    result = await self.dispatch_request(request_context)
  File "/home/runner/Tinsml/venv/lib/python3.8/site-packages/quart/app.py", line 1557, in dispatch_request
    return await self.ensure_async(handler)(**request_.view_args)
  File "server.py", line 18, in home
    return await render_template("home.html")
  File "/home/runner/Tinsml/venv/lib/python3.8/site-packages/quart/templating.py", line 91, in render_template
    return await _render(template, context, current_app._get_current_object())  # type: ignore
  File "/home/runner/Tinsml/venv/lib/python3.8/site-packages/quart/templating.py", line 108, in _render
    rendered_template = await template.render_async(context)
  File "/home/runner/Tinsml/venv/lib/python3.8/site-packages/jinja2/environment.py", line 1324, in render_async
    return self.environment.handle_exception()
  File "/home/runner/Tinsml/venv/lib/python3.8/site-packages/jinja2/environment.py", line 936, in handle_exception
    raise rewrite_traceback_stack(source=source)
  File "/home/runner/Tinsml/venv/lib/python3.8/site-packages/jinja2/environment.py", line 1321, in <listcomp>
    [n async for n in self.root_render_func(ctx)]  # type: ignore
  File "/home/runner/Tinsml/templates/home.html", line 1, in top-level template code
    {% extends 'base.html' %}
  File "/home/runner/Tinsml/venv/lib/python3.8/site-packages/jinja2/environment.py", line 936, in handle_exception
    raise rewrite_traceback_stack(source=source)
  File "/home/runner/Tinsml/templates/base.html", line 275, in template
    {% block ext_head %} {% endblock %
jinja2.exceptions.TemplateSyntaxError: expected token 'end of statement block', got '%'
Exception on request GET /
Traceback (most recent call last):
  File "/home/runner/Tinsml/venv/lib/python3.8/site-packages/quart/app.py", line 1489, in handle_request
    return await self.full_dispatch_request(request_context)
  File "/home/runner/Tinsml/venv/lib/python3.8/site-packages/quart/app.py", line 1514, in full_dispatch_request
    result = await self.handle_user_exception(error)
  File "/home/runner/Tinsml/venv/lib/python3.8/site-packages/quart/app.py", line 964, in handle_user_exception
    raise error
  File "/home/runner/Tinsml/venv/lib/python3.8/site-packages/quart/app.py", line 1512, in full_dispatch_request
    result = await self.dispatch_request(request_context)
  File "/home/runner/Tinsml/venv/lib/python3.8/site-packages/quart/app.py", line 1557, in dispatch_request
    return await self.ensure_async(handler)(**request_.view_args)
  File "server.py", line 18, in home
    return await render_template("home.html")
  File "/home/runner/Tinsml/venv/lib/python3.8/site-packages/quart/templating.py", line 91, in render_template
    return await _render(template, context, current_app._get_current_object())  # type: ignore
  File "/home/runner/Tinsml/venv/lib/python3.8/site-packages/quart/templating.py", line 108, in _render
    rendered_template = await template.render_async(context)
  File "/home/runner/Tinsml/venv/lib/python3.8/site-packages/jinja2/environment.py", line 1324, in render_async
    return self.environment.handle_exception()
  File "/home/runner/Tinsml/venv/lib/python3.8/site-packages/jinja2/environment.py", line 936, in handle_exception
    raise rewrite_traceback_stack(source=source)
  File "/home/runner/Tinsml/venv/lib/python3.8/site-packages/jinja2/environment.py", line 1321, in <listcomp>
    [n async for n in self.root_render_func(ctx)]  # type: ignore
  File "/home/runner/Tinsml/templates/home.html", line 1, in top-level template code
    {% extends 'base.html' %}
  File "/home/runner/Tinsml/venv/lib/python3.8/site-packages/jinja2/environment.py", line 936, in handle_exception
    raise rewrite_traceback_stack(source=source)
  File "/home/runner/Tinsml/templates/base.html", line 275, in template
    {% block ext_head %} {% endblock %
jinja2.exceptions.TemplateSyntaxError: expected token 'end of statement block', got '%'
Exception on request GET /
Traceback (most recent call last):
  File "/home/runner/Tinsml/venv/lib/python3.8/site-packages/quart/app.py", line 1489, in handle_request
    return await self.full_dispatch_request(request_context)
  File "/home/runner/Tinsml/venv/lib/python3.8/site-packages/quart/app.py", line 1514, in full_dispatch_request
    result = await self.handle_user_exception(error)
  File "/home/runner/Tinsml/venv/lib/python3.8/site-packages/quart/app.py", line 964, in handle_user_exception
    raise error
  File "/home/runner/Tinsml/venv/lib/python3.8/site-packages/quart/app.py", line 1512, in full_dispatch_request
    result = await self.dispatch_request(request_context)
  File "/home/runner/Tinsml/venv/lib/python3.8/site-packages/quart/app.py", line 1557, in dispatch_request
    return await self.ensure_async(handler)(**request_.view_args)
  File "server.py", line 18, in home
    return await render_template("home.html")
  File "/home/runner/Tinsml/venv/lib/python3.8/site-packages/quart/templating.py", line 91, in render_template
    return await _render(template, context, current_app._get_current_object())  # type: ignore
  File "/home/runner/Tinsml/venv/lib/python3.8/site-packages/quart/templating.py", line 108, in _render
    rendered_template = await template.render_async(context)
  File "/home/runner/Tinsml/venv/lib/python3.8/site-packages/jinja2/environment.py", line 1324, in render_async
    return self.environment.handle_exception()
  File "/home/runner/Tinsml/venv/lib/python3.8/site-packages/jinja2/environment.py", line 936, in handle_exception
    raise rewrite_traceback_stack(source=source)
  File "/home/runner/Tinsml/venv/lib/python3.8/site-packages/jinja2/environment.py", line 1321, in <listcomp>
    [n async for n in self.root_render_func(ctx)]  # type: ignore
  File "/home/runner/Tinsml/templates/home.html", line 1, in top-level template code
    {% extends 'base.html' %}
  File "/home/runner/Tinsml/venv/lib/python3.8/site-packages/jinja2/environment.py", line 936, in handle_exception
    raise rewrite_traceback_stack(source=source)
  File "/home/runner/Tinsml/templates/base.html", line 275, in template
    {% block ext_head %} {% endblock %
jinja2.exceptions.TemplateSyntaxError: expected token 'end of statement block', got '%'
Exception on request GET /
Traceback (most recent call last):
  File "/home/runner/Tinsml/venv/lib/python3.8/site-packages/quart/app.py", line 1489, in handle_request
    return await self.full_dispatch_request(request_context)
  File "/home/runner/Tinsml/venv/lib/python3.8/site-packages/quart/app.py", line 1514, in full_dispatch_request
    result = await self.handle_user_exception(error)
  File "/home/runner/Tinsml/venv/lib/python3.8/site-packages/quart/app.py", line 964, in handle_user_exception
    raise error
  File "/home/runner/Tinsml/venv/lib/python3.8/site-packages/quart/app.py", line 1512, in full_dispatch_request
    result = await self.dispatch_request(request_context)
  File "/home/runner/Tinsml/venv/lib/python3.8/site-packages/quart/app.py", line 1557, in dispatch_request
    return await self.ensure_async(handler)(**request_.view_args)
  File "server.py", line 18, in home
    return await render_template("home.html")
  File "/home/runner/Tinsml/venv/lib/python3.8/site-packages/quart/templating.py", line 91, in render_template
    return await _render(template, context, current_app._get_current_object())  # type: ignore
  File "/home/runner/Tinsml/venv/lib/python3.8/site-packages/quart/templating.py", line 108, in _render
    rendered_template = await template.render_async(context)
  File "/home/runner/Tinsml/venv/lib/python3.8/site-packages/jinja2/environment.py", line 1324, in render_async
    return self.environment.handle_exception()
  File "/home/runner/Tinsml/venv/lib/python3.8/site-packages/jinja2/environment.py", line 936, in handle_exception
    raise rewrite_traceback_stack(source=source)
  File "/home/runner/Tinsml/venv/lib/python3.8/site-packages/jinja2/environment.py", line 1321, in <listcomp>
    [n async for n in self.root_render_func(ctx)]  # type: ignore
  File "/home/runner/Tinsml/templates/home.html", line 1, in top-level template code
    {% extends 'base.html' %}
  File "/home/runner/Tinsml/venv/lib/python3.8/site-packages/jinja2/environment.py", line 936, in handle_exception
    raise rewrite_traceback_stack(source=source)
  File "/home/runner/Tinsml/templates/base.html", line 275, in template
    {% block ext_head %} {% endblock %
jinja2.exceptions.TemplateSyntaxError: expected token 'end of statement block', got '%'
Exception on request GET /
Traceback (most recent call last):
  File "/home/runner/Tinsml/venv/lib/python3.8/site-packages/quart/app.py", line 1489, in handle_request
    return await self.full_dispatch_request(request_context)
  File "/home/runner/Tinsml/venv/lib/python3.8/site-packages/quart/app.py", line 1514, in full_dispatch_request
    result = await self.handle_user_exception(error)
  File "/home/runner/Tinsml/venv/lib/python3.8/site-packages/quart/app.py", line 964, in handle_user_exception
    raise error
  File "/home/runner/Tinsml/venv/lib/python3.8/site-packages/quart/app.py", line 1512, in full_dispatch_request
    result = await self.dispatch_request(request_context)
  File "/home/runner/Tinsml/venv/lib/python3.8/site-packages/quart/app.py", line 1557, in dispatch_request
    return await self.ensure_async(handler)(**request_.view_args)
  File "server.py", line 18, in home
    return await render_template("home.html")
  File "/home/runner/Tinsml/venv/lib/python3.8/site-packages/quart/templating.py", line 91, in render_template
    return await _render(template, context, current_app._get_current_object())  # type: ignore
  File "/home/runner/Tinsml/venv/lib/python3.8/site-packages/quart/templating.py", line 108, in _render
    rendered_template = await template.render_async(context)
  File "/home/runner/Tinsml/venv/lib/python3.8/site-packages/jinja2/environment.py", line 1324, in render_async
    return self.environment.handle_exception()
  File "/home/runner/Tinsml/venv/lib/python3.8/site-packages/jinja2/environment.py", line 936, in handle_exception
    raise rewrite_traceback_stack(source=source)
  File "/home/runner/Tinsml/venv/lib/python3.8/site-packages/jinja2/environment.py", line 1321, in <listcomp>
    [n async for n in self.root_render_func(ctx)]  # type: ignore
  File "/home/runner/Tinsml/templates/home.html", line 1, in top-level template code
    {% extends 'base.html' %}
  File "/home/runner/Tinsml/venv/lib/python3.8/site-packages/jinja2/environment.py", line 936, in handle_exception
    raise rewrite_traceback_stack(source=source)
  File "/home/runner/Tinsml/templates/base.html", line 275, in template
    {% block ext_head %} {% endblock %
jinja2.exceptions.TemplateSyntaxError: expected token 'end of statement block', got '%'
Exception on request GET /
Traceback (most recent call last):
  File "/home/runner/Tinsml/venv/lib/python3.8/site-packages/quart/app.py", line 1489, in handle_request
    return await self.full_dispatch_request(request_context)
  File "/home/runner/Tinsml/venv/lib/python3.8/site-packages/quart/app.py", line 1514, in full_dispatch_request
    result = await self.handle_user_exception(error)
  File "/home/runner/Tinsml/venv/lib/python3.8/site-packages/quart/app.py", line 964, in handle_user_exception
    raise error
  File "/home/runner/Tinsml/venv/lib/python3.8/site-packages/quart/app.py", line 1512, in full_dispatch_request
    result = await self.dispatch_request(request_context)
  File "/home/runner/Tinsml/venv/lib/python3.8/site-packages/quart/app.py", line 1557, in dispatch_request
    return await self.ensure_async(handler)(**request_.view_args)
  File "server.py", line 18, in home
    return await render_template("home.html")
  File "/home/runner/Tinsml/venv/lib/python3.8/site-packages/quart/templating.py", line 91, in render_template
    return await _render(template, context, current_app._get_current_object())  # type: ignore
  File "/home/runner/Tinsml/venv/lib/python3.8/site-packages/quart/templating.py", line 108, in _render
    rendered_template = await template.render_async(context)
  File "/home/runner/Tinsml/venv/lib/python3.8/site-packages/jinja2/environment.py", line 1324, in render_async
    return self.environment.handle_exception()
  File "/home/runner/Tinsml/venv/lib/python3.8/site-packages/jinja2/environment.py", line 936, in handle_exception
    raise rewrite_traceback_stack(source=source)
  File "/home/runner/Tinsml/venv/lib/python3.8/site-packages/jinja2/environment.py", line 1321, in <listcomp>
    [n async for n in self.root_render_func(ctx)]  # type: ignore
  File "/home/runner/Tinsml/templates/home.html", line 1, in top-level template code
    {% extends 'base.html' %}
  File "/home/runner/Tinsml/venv/lib/python3.8/site-packages/jinja2/environment.py", line 936, in handle_exception
    raise rewrite_traceback_stack(source=source)
  File "/home/runner/Tinsml/templates/base.html", line 275, in template
    {% block ext_head %} {% endblock %
jinja2.exceptions.TemplateSyntaxError: expected token 'end of statement block', got '%'
Exception on request GET /
Traceback (most recent call last):
  File "/home/runner/Tinsml/venv/lib/python3.8/site-packages/quart/app.py", line 1489, in handle_request
    return await self.full_dispatch_request(request_context)
  File "/home/runner/Tinsml/venv/lib/python3.8/site-packages/quart/app.py", line 1514, in full_dispatch_request
    result = await self.handle_user_exception(error)
  File "/home/runner/Tinsml/venv/lib/python3.8/site-packages/quart/app.py", line 964, in handle_user_exception
    raise error
  File "/home/runner/Tinsml/venv/lib/python3.8/site-packages/quart/app.py", line 1512, in full_dispatch_request
    result = await self.dispatch_request(request_context)
  File "/home/runner/Tinsml/venv/lib/python3.8/site-packages/quart/app.py", line 1557, in dispatch_request
    return await self.ensure_async(handler)(**request_.view_args)
  File "server.py", line 18, in home
    return await render_template("home.html")
  File "/home/runner/Tinsml/venv/lib/python3.8/site-packages/quart/templating.py", line 91, in render_template
    return await _render(template, context, current_app._get_current_object())  # type: ignore
  File "/home/runner/Tinsml/venv/lib/python3.8/site-packages/quart/templating.py", line 108, in _render
    rendered_template = await template.render_async(context)
  File "/home/runner/Tinsml/venv/lib/python3.8/site-packages/jinja2/environment.py", line 1324, in render_async
    return self.environment.handle_exception()
  File "/home/runner/Tinsml/venv/lib/python3.8/site-packages/jinja2/environment.py", line 936, in handle_exception
    raise rewrite_traceback_stack(source=source)
  File "/home/runner/Tinsml/venv/lib/python3.8/site-packages/jinja2/environment.py", line 1321, in <listcomp>
    [n async for n in self.root_render_func(ctx)]  # type: ignore
  File "/home/runner/Tinsml/templates/home.html", line 1, in top-level template code
    {% extends 'base.html' %}
  File "/home/runner/Tinsml/venv/lib/python3.8/site-packages/jinja2/environment.py", line 936, in handle_exception
    raise rewrite_traceback_stack(source=source)
  File "/home/runner/Tinsml/templates/base.html", line 275, in template
    {% block ext_head %} {% endblock %
jinja2.exceptions.TemplateSyntaxError: expected token 'end of statement block', got '%'
Exception on request GET /
Traceback (most recent call last):
  File "/home/runner/Tinsml/venv/lib/python3.8/site-packages/quart/app.py", line 1489, in handle_request
    return await self.full_dispatch_request(request_context)
  File "/home/runner/Tinsml/venv/lib/python3.8/site-packages/quart/app.py", line 1514, in full_dispatch_request
    result = await self.handle_user_exception(error)
  File "/home/runner/Tinsml/venv/lib/python3.8/site-packages/quart/app.py", line 964, in handle_user_exception
    raise error
  File "/home/runner/Tinsml/venv/lib/python3.8/site-packages/quart/app.py", line 1512, in full_dispatch_request
    result = await self.dispatch_request(request_context)
  File "/home/runner/Tinsml/venv/lib/python3.8/site-packages/quart/app.py", line 1557, in dispatch_request
    return await self.ensure_async(handler)(**request_.view_args)
  File "server.py", line 18, in home
    return await render_template("home.html")
  File "/home/runner/Tinsml/venv/lib/python3.8/site-packages/quart/templating.py", line 91, in render_template
    return await _render(template, context, current_app._get_current_object())  # type: ignore
  File "/home/runner/Tinsml/venv/lib/python3.8/site-packages/quart/templating.py", line 108, in _render
    rendered_template = await template.render_async(context)
  File "/home/runner/Tinsml/venv/lib/python3.8/site-packages/jinja2/environment.py", line 1324, in render_async
    return self.environment.handle_exception()
  File "/home/runner/Tinsml/venv/lib/python3.8/site-packages/jinja2/environment.py", line 936, in handle_exception
    raise rewrite_traceback_stack(source=source)
  File "/home/runner/Tinsml/venv/lib/python3.8/site-packages/jinja2/environment.py", line 1321, in <listcomp>
    [n async for n in self.root_render_func(ctx)]  # type: ignore
  File "/home/runner/Tinsml/templates/home.html", line 1, in top-level template code
    {% extends 'base.html' %}
  File "/home/runner/Tinsml/venv/lib/python3.8/site-packages/jinja2/environment.py", line 936, in handle_exception
    raise rewrite_traceback_stack(source=source)
  File "/home/runner/Tinsml/templates/base.html", line 275, in template
    {% block ext_head %} {% endblock %
jinja2.exceptions.TemplateSyntaxError: expected token 'end of statement block', got '%'
Exception on request GET /
Traceback (most recent call last):
  File "/home/runner/Tinsml/venv/lib/python3.8/site-packages/quart/app.py", line 1489, in handle_request
    return await self.full_dispatch_request(request_context)
  File "/home/runner/Tinsml/venv/lib/python3.8/site-packages/quart/app.py", line 1514, in full_dispatch_request
    result = await self.handle_user_exception(error)
  File "/home/runner/Tinsml/venv/lib/python3.8/site-packages/quart/app.py", line 964, in handle_user_exception
    raise error
  File "/home/runner/Tinsml/venv/lib/python3.8/site-packages/quart/app.py", line 1512, in full_dispatch_request
    result = await self.dispatch_request(request_context)
  File "/home/runner/Tinsml/venv/lib/python3.8/site-packages/quart/app.py", line 1557, in dispatch_request
    return await self.ensure_async(handler)(**request_.view_args)
  File "server.py", line 18, in home
    return await render_template("home.html")
  File "/home/runner/Tinsml/venv/lib/python3.8/site-packages/quart/templating.py", line 91, in render_template
    return await _render(template, context, current_app._get_current_object())  # type: ignore
  File "/home/runner/Tinsml/venv/lib/python3.8/site-packages/quart/templating.py", line 108, in _render
    rendered_template = await template.render_async(context)
  File "/home/runner/Tinsml/venv/lib/python3.8/site-packages/jinja2/environment.py", line 1324, in render_async
    return self.environment.handle_exception()
  File "/home/runner/Tinsml/venv/lib/python3.8/site-packages/jinja2/environment.py", line 936, in handle_exception
    raise rewrite_traceback_stack(source=source)
  File "/home/runner/Tinsml/venv/lib/python3.8/site-packages/jinja2/environment.py", line 1321, in <listcomp>
    [n async for n in self.root_render_func(ctx)]  # type: ignore
  File "/home/runner/Tinsml/templates/home.html", line 1, in top-level template code
    {% extends 'base.html' %}
  File "/home/runner/Tinsml/venv/lib/python3.8/site-packages/jinja2/environment.py", line 936, in handle_exception
    raise rewrite_traceback_stack(source=source)
  File "/home/runner/Tinsml/templates/base.html", line 275, in template
    {% block ext_head %} {% endblock %
jinja2.exceptions.TemplateSyntaxError: expected token 'end of statement block', got '%'
Exception on request GET /
Traceback (most recent call last):
  File "/home/runner/Tinsml/venv/lib/python3.8/site-packages/quart/app.py", line 1489, in handle_request
    return await self.full_dispatch_request(request_context)
  File "/home/runner/Tinsml/venv/lib/python3.8/site-packages/quart/app.py", line 1514, in full_dispatch_request
    result = await self.handle_user_exception(error)
  File "/home/runner/Tinsml/venv/lib/python3.8/site-packages/quart/app.py", line 964, in handle_user_exception
    raise error
  File "/home/runner/Tinsml/venv/lib/python3.8/site-packages/quart/app.py", line 1512, in full_dispatch_request
    result = await self.dispatch_request(request_context)
  File "/home/runner/Tinsml/venv/lib/python3.8/site-packages/quart/app.py", line 1557, in dispatch_request
    return await self.ensure_async(handler)(**request_.view_args)
  File "server.py", line 18, in home
    return await render_template("home.html")
  File "/home/runner/Tinsml/venv/lib/python3.8/site-packages/quart/templating.py", line 91, in render_template
    return await _render(template, context, current_app._get_current_object())  # type: ignore
  File "/home/runner/Tinsml/venv/lib/python3.8/site-packages/quart/templating.py", line 108, in _render
    rendered_template = await template.render_async(context)
  File "/home/runner/Tinsml/venv/lib/python3.8/site-packages/jinja2/environment.py", line 1324, in render_async
    return self.environment.handle_exception()
  File "/home/runner/Tinsml/venv/lib/python3.8/site-packages/jinja2/environment.py", line 936, in handle_exception
    raise rewrite_traceback_stack(source=source)
  File "/home/runner/Tinsml/venv/lib/python3.8/site-packages/jinja2/environment.py", line 1321, in <listcomp>
    [n async for n in self.root_render_func(ctx)]  # type: ignore
  File "/home/runner/Tinsml/templates/home.html", line 1, in top-level template code
    {% extends 'base.html' %}
  File "/home/runner/Tinsml/venv/lib/python3.8/site-packages/jinja2/environment.py", line 936, in handle_exception
    raise rewrite_traceback_stack(source=source)
  File "/home/runner/Tinsml/templates/base.html", line 275, in template
    {% block ext_head %} {% endblock %
jinja2.exceptions.TemplateSyntaxError: expected token 'end of statement block', got '%'
Exception on request GET /
Traceback (most recent call last):
  File "/home/runner/Tinsml/venv/lib/python3.8/site-packages/quart/app.py", line 1489, in handle_request
    return await self.full_dispatch_request(request_context)
  File "/home/runner/Tinsml/venv/lib/python3.8/site-packages/quart/app.py", line 1514, in full_dispatch_request
    result = await self.handle_user_exception(error)
  File "/home/runner/Tinsml/venv/lib/python3.8/site-packages/quart/app.py", line 964, in handle_user_exception
    raise error
  File "/home/runner/Tinsml/venv/lib/python3.8/site-packages/quart/app.py", line 1512, in full_dispatch_request
    result = await self.dispatch_request(request_context)
  File "/home/runner/Tinsml/venv/lib/python3.8/site-packages/quart/app.py", line 1557, in dispatch_request
    return await self.ensure_async(handler)(**request_.view_args)
  File "server.py", line 18, in home
    return await render_template("home.html")
  File "/home/runner/Tinsml/venv/lib/python3.8/site-packages/quart/templating.py", line 91, in render_template
    return await _render(template, context, current_app._get_current_object())  # type: ignore
  File "/home/runner/Tinsml/venv/lib/python3.8/site-packages/quart/templating.py", line 108, in _render
    rendered_template = await template.render_async(context)
  File "/home/runner/Tinsml/venv/lib/python3.8/site-packages/jinja2/environment.py", line 1324, in render_async
    return self.environment.handle_exception()
  File "/home/runner/Tinsml/venv/lib/python3.8/site-packages/jinja2/environment.py", line 936, in handle_exception
    raise rewrite_traceback_stack(source=source)
  File "/home/runner/Tinsml/venv/lib/python3.8/site-packages/jinja2/environment.py", line 1321, in <listcomp>
    [n async for n in self.root_render_func(ctx)]  # type: ignore
  File "/home/runner/Tinsml/templates/home.html", line 1, in top-level template code
    {% extends 'base.html' %}
  File "/home/runner/Tinsml/venv/lib/python3.8/site-packages/jinja2/environment.py", line 936, in handle_exception
    raise rewrite_traceback_stack(source=source)
  File "/home/runner/Tinsml/templates/base.html", line 275, in template
    {% block ext_head %} {% endblock %
jinja2.exceptions.TemplateSyntaxError: expected token 'end of statement block', got '%'
Exception on request GET /
Traceback (most recent call last):
  File "/home/runner/Tinsml/venv/lib/python3.8/site-packages/quart/app.py", line 1489, in handle_request
    return await self.full_dispatch_request(request_context)
  File "/home/runner/Tinsml/venv/lib/python3.8/site-packages/quart/app.py", line 1514, in full_dispatch_request
    result = await self.handle_user_exception(error)
  File "/home/runner/Tinsml/venv/lib/python3.8/site-packages/quart/app.py", line 964, in handle_user_exception
    raise error
  File "/home/runner/Tinsml/venv/lib/python3.8/site-packages/quart/app.py", line 1512, in full_dispatch_request
    result = await self.dispatch_request(request_context)
  File "/home/runner/Tinsml/venv/lib/python3.8/site-packages/quart/app.py", line 1557, in dispatch_request
    return await self.ensure_async(handler)(**request_.view_args)
  File "server.py", line 18, in home
    return await render_template("home.html")
  File "/home/runner/Tinsml/venv/lib/python3.8/site-packages/quart/templating.py", line 91, in render_template
    return await _render(template, context, current_app._get_current_object())  # type: ignore
  File "/home/runner/Tinsml/venv/lib/python3.8/site-packages/quart/templating.py", line 108, in _render
    rendered_template = await template.render_async(context)
  File "/home/runner/Tinsml/venv/lib/python3.8/site-packages/jinja2/environment.py", line 1324, in render_async
    return self.environment.handle_exception()
  File "/home/runner/Tinsml/venv/lib/python3.8/site-packages/jinja2/environment.py", line 936, in handle_exception
    raise rewrite_traceback_stack(source=source)
  File "/home/runner/Tinsml/venv/lib/python3.8/site-packages/jinja2/environment.py", line 1321, in <listcomp>
    [n async for n in self.root_render_func(ctx)]  # type: ignore
  File "/home/runner/Tinsml/templates/home.html", line 1, in top-level template code
    {% extends 'base.html' %}
  File "/home/runner/Tinsml/venv/lib/python3.8/site-packages/jinja2/environment.py", line 936, in handle_exception
    raise rewrite_traceback_stack(source=source)
  File "/home/runner/Tinsml/templates/base.html", line 275, in template
    {% block ext_head %} {% endblock %
jinja2.exceptions.TemplateSyntaxError: expected token 'end of statement block', got '%'
Exception on request GET /
Traceback (most recent call last):
  File "/home/runner/Tinsml/venv/lib/python3.8/site-packages/quart/app.py", line 1489, in handle_request
    return await self.full_dispatch_request(request_context)
  File "/home/runner/Tinsml/venv/lib/python3.8/site-packages/quart/app.py", line 1514, in full_dispatch_request
    result = await self.handle_user_exception(error)
  File "/home/runner/Tinsml/venv/lib/python3.8/site-packages/quart/app.py", line 964, in handle_user_exception
    raise error
  File "/home/runner/Tinsml/venv/lib/python3.8/site-packages/quart/app.py", line 1512, in full_dispatch_request
    result = await self.dispatch_request(request_context)
  File "/home/runner/Tinsml/venv/lib/python3.8/site-packages/quart/app.py", line 1557, in dispatch_request
    return await self.ensure_async(handler)(**request_.view_args)
  File "server.py", line 18, in home
    return await render_template("home.html")
  File "/home/runner/Tinsml/venv/lib/python3.8/site-packages/quart/templating.py", line 90, in render_template
    template = current_app.jinja_env.get_or_select_template(template_name_or_list)  # type: ignore
  File "/home/runner/Tinsml/venv/lib/python3.8/site-packages/jinja2/environment.py", line 1081, in get_or_select_template
    return self.get_template(template_name_or_list, parent, globals)
  File "/home/runner/Tinsml/venv/lib/python3.8/site-packages/jinja2/environment.py", line 1010, in get_template
    return self._load_template(name, globals)
  File "/home/runner/Tinsml/venv/lib/python3.8/site-packages/jinja2/environment.py", line 969, in _load_template
    template = self.loader.load(self, name, self.make_globals(globals))
  File "/home/runner/Tinsml/venv/lib/python3.8/site-packages/jinja2/loaders.py", line 138, in load
    code = environment.compile(source, name, filename)
  File "/home/runner/Tinsml/venv/lib/python3.8/site-packages/jinja2/environment.py", line 768, in compile
    self.handle_exception(source=source_hint)
  File "/home/runner/Tinsml/venv/lib/python3.8/site-packages/jinja2/environment.py", line 936, in handle_exception
    raise rewrite_traceback_stack(source=source)
  File "/home/runner/Tinsml/templates/home.html", line 10, in template
    {% endblock %}
jinja2.exceptions.TemplateSyntaxError: Unexpected end of template. Jinja was looking for the following tags: 'endblock'. The innermost block that needs to be closed is 'block'.
Exception on request GET /
Traceback (most recent call last):
  File "/home/runner/Tinsml/venv/lib/python3.8/site-packages/quart/app.py", line 1489, in handle_request
    return await self.full_dispatch_request(request_context)
  File "/home/runner/Tinsml/venv/lib/python3.8/site-packages/quart/app.py", line 1514, in full_dispatch_request
    result = await self.handle_user_exception(error)
  File "/home/runner/Tinsml/venv/lib/python3.8/site-packages/quart/app.py", line 964, in handle_user_exception
    raise error
  File "/home/runner/Tinsml/venv/lib/python3.8/site-packages/quart/app.py", line 1512, in full_dispatch_request
    result = await self.dispatch_request(request_context)
  File "/home/runner/Tinsml/venv/lib/python3.8/site-packages/quart/app.py", line 1557, in dispatch_request
    return await self.ensure_async(handler)(**request_.view_args)
  File "server.py", line 18, in home
    return await render_template("home.html")
  File "/home/runner/Tinsml/venv/lib/python3.8/site-packages/quart/templating.py", line 90, in render_template
    template = current_app.jinja_env.get_or_select_template(template_name_or_list)  # type: ignore
  File "/home/runner/Tinsml/venv/lib/python3.8/site-packages/jinja2/environment.py", line 1081, in get_or_select_template
    return self.get_template(template_name_or_list, parent, globals)
  File "/home/runner/Tinsml/venv/lib/python3.8/site-packages/jinja2/environment.py", line 1010, in get_template
    return self._load_template(name, globals)
  File "/home/runner/Tinsml/venv/lib/python3.8/site-packages/jinja2/environment.py", line 969, in _load_template
    template = self.loader.load(self, name, self.make_globals(globals))
  File "/home/runner/Tinsml/venv/lib/python3.8/site-packages/jinja2/loaders.py", line 138, in load
    code = environment.compile(source, name, filename)
  File "/home/runner/Tinsml/venv/lib/python3.8/site-packages/jinja2/environment.py", line 768, in compile
    self.handle_exception(source=source_hint)
  File "/home/runner/Tinsml/venv/lib/python3.8/site-packages/jinja2/environment.py", line 936, in handle_exception
    raise rewrite_traceback_stack(source=source)
  File "/home/runner/Tinsml/templates/home.html", line 10, in template
    {% endblock %}
jinja2.exceptions.TemplateSyntaxError: Unexpected end of template. Jinja was looking for the following tags: 'endblock'. The innermost block that needs to be closed is 'block'.
Exception on request GET /
Traceback (most recent call last):
  File "/home/runner/Tinsml/venv/lib/python3.8/site-packages/quart/app.py", line 1489, in handle_request
    return await self.full_dispatch_request(request_context)
  File "/home/runner/Tinsml/venv/lib/python3.8/site-packages/quart/app.py", line 1514, in full_dispatch_request
    result = await self.handle_user_exception(error)
  File "/home/runner/Tinsml/venv/lib/python3.8/site-packages/quart/app.py", line 964, in handle_user_exception
    raise error
  File "/home/runner/Tinsml/venv/lib/python3.8/site-packages/quart/app.py", line 1512, in full_dispatch_request
    result = await self.dispatch_request(request_context)
  File "/home/runner/Tinsml/venv/lib/python3.8/site-packages/quart/app.py", line 1557, in dispatch_request
    return await self.ensure_async(handler)(**request_.view_args)
  File "server.py", line 18, in home
    return await render_template("home.html")
  File "/home/runner/Tinsml/venv/lib/python3.8/site-packages/quart/templating.py", line 91, in render_template
    return await _render(template, context, current_app._get_current_object())  # type: ignore
  File "/home/runner/Tinsml/venv/lib/python3.8/site-packages/quart/templating.py", line 108, in _render
    rendered_template = await template.render_async(context)
  File "/home/runner/Tinsml/venv/lib/python3.8/site-packages/jinja2/environment.py", line 1324, in render_async
    return self.environment.handle_exception()
  File "/home/runner/Tinsml/venv/lib/python3.8/site-packages/jinja2/environment.py", line 936, in handle_exception
    raise rewrite_traceback_stack(source=source)
  File "/home/runner/Tinsml/venv/lib/python3.8/site-packages/jinja2/environment.py", line 1321, in <listcomp>
    [n async for n in self.root_render_func(ctx)]  # type: ignore
  File "/home/runner/Tinsml/templates/home.html", line 1, in top-level template code
    {% extends 'base.html' %}
  File "/home/runner/Tinsml/venv/lib/python3.8/site-packages/jinja2/environment.py", line 936, in handle_exception
    raise rewrite_traceback_stack(source=source)
  File "/home/runner/Tinsml/templates/base.html", line 424, in template
    {% block ct_nobulma}
jinja2.exceptions.TemplateSyntaxError: unexpected '}'
Exception on request GET /
Traceback (most recent call last):
  File "/home/runner/Tinsml/venv/lib/python3.8/site-packages/quart/app.py", line 1489, in handle_request
    return await self.full_dispatch_request(request_context)
  File "/home/runner/Tinsml/venv/lib/python3.8/site-packages/quart/app.py", line 1514, in full_dispatch_request
    result = await self.handle_user_exception(error)
  File "/home/runner/Tinsml/venv/lib/python3.8/site-packages/quart/app.py", line 964, in handle_user_exception
    raise error
  File "/home/runner/Tinsml/venv/lib/python3.8/site-packages/quart/app.py", line 1512, in full_dispatch_request
    result = await self.dispatch_request(request_context)
  File "/home/runner/Tinsml/venv/lib/python3.8/site-packages/quart/app.py", line 1557, in dispatch_request
    return await self.ensure_async(handler)(**request_.view_args)
  File "server.py", line 18, in home
    return await render_template("home.html")
  File "/home/runner/Tinsml/venv/lib/python3.8/site-packages/quart/templating.py", line 91, in render_template
    return await _render(template, context, current_app._get_current_object())  # type: ignore
  File "/home/runner/Tinsml/venv/lib/python3.8/site-packages/quart/templating.py", line 108, in _render
    rendered_template = await template.render_async(context)
  File "/home/runner/Tinsml/venv/lib/python3.8/site-packages/jinja2/environment.py", line 1324, in render_async
    return self.environment.handle_exception()
  File "/home/runner/Tinsml/venv/lib/python3.8/site-packages/jinja2/environment.py", line 936, in handle_exception
    raise rewrite_traceback_stack(source=source)
  File "/home/runner/Tinsml/venv/lib/python3.8/site-packages/jinja2/environment.py", line 1321, in <listcomp>
    [n async for n in self.root_render_func(ctx)]  # type: ignore
  File "/home/runner/Tinsml/templates/home.html", line 1, in top-level template code
    {% extends 'base.html' %}
  File "/home/runner/Tinsml/venv/lib/python3.8/site-packages/jinja2/environment.py", line 936, in handle_exception
    raise rewrite_traceback_stack(source=source)
  File "/home/runner/Tinsml/templates/base.html", line 424, in template
    {% block ct_nobulma}
jinja2.exceptions.TemplateSyntaxError: unexpected '}'
Exception on request GET /
Traceback (most recent call last):
  File "/home/runner/Tinsml/venv/lib/python3.8/site-packages/quart/app.py", line 1489, in handle_request
    return await self.full_dispatch_request(request_context)
  File "/home/runner/Tinsml/venv/lib/python3.8/site-packages/quart/app.py", line 1514, in full_dispatch_request
    result = await self.handle_user_exception(error)
  File "/home/runner/Tinsml/venv/lib/python3.8/site-packages/quart/app.py", line 964, in handle_user_exception
    raise error
  File "/home/runner/Tinsml/venv/lib/python3.8/site-packages/quart/app.py", line 1512, in full_dispatch_request
    result = await self.dispatch_request(request_context)
  File "/home/runner/Tinsml/venv/lib/python3.8/site-packages/quart/app.py", line 1557, in dispatch_request
    return await self.ensure_async(handler)(**request_.view_args)
  File "server.py", line 18, in home
    return await render_template("home.html")
  File "/home/runner/Tinsml/venv/lib/python3.8/site-packages/quart/templating.py", line 91, in render_template
    return await _render(template, context, current_app._get_current_object())  # type: ignore
  File "/home/runner/Tinsml/venv/lib/python3.8/site-packages/quart/templating.py", line 108, in _render
    rendered_template = await template.render_async(context)
  File "/home/runner/Tinsml/venv/lib/python3.8/site-packages/jinja2/environment.py", line 1324, in render_async
    return self.environment.handle_exception()
  File "/home/runner/Tinsml/venv/lib/python3.8/site-packages/jinja2/environment.py", line 936, in handle_exception
    raise rewrite_traceback_stack(source=source)
  File "/home/runner/Tinsml/venv/lib/python3.8/site-packages/jinja2/environment.py", line 1321, in <listcomp>
    [n async for n in self.root_render_func(ctx)]  # type: ignore
  File "/home/runner/Tinsml/templates/home.html", line 1, in top-level template code
    {% extends 'base.html' %}
  File "/home/runner/Tinsml/venv/lib/python3.8/site-packages/jinja2/environment.py", line 936, in handle_exception
    raise rewrite_traceback_stack(source=source)
  File "/home/runner/Tinsml/templates/base.html", line 424, in template
    {% block ct_nobulma}
jinja2.exceptions.TemplateSyntaxError: unexpected '}'
Exception on request GET /
Traceback (most recent call last):
  File "/home/runner/Tinsml/venv/lib/python3.8/site-packages/quart/app.py", line 1489, in handle_request
    return await self.full_dispatch_request(request_context)
  File "/home/runner/Tinsml/venv/lib/python3.8/site-packages/quart/app.py", line 1514, in full_dispatch_request
    result = await self.handle_user_exception(error)
  File "/home/runner/Tinsml/venv/lib/python3.8/site-packages/quart/app.py", line 964, in handle_user_exception
    raise error
  File "/home/runner/Tinsml/venv/lib/python3.8/site-packages/quart/app.py", line 1512, in full_dispatch_request
    result = await self.dispatch_request(request_context)
  File "/home/runner/Tinsml/venv/lib/python3.8/site-packages/quart/app.py", line 1557, in dispatch_request
    return await self.ensure_async(handler)(**request_.view_args)
  File "server.py", line 18, in home
    return await render_template("home.html")
  File "/home/runner/Tinsml/venv/lib/python3.8/site-packages/quart/templating.py", line 91, in render_template
    return await _render(template, context, current_app._get_current_object())  # type: ignore
  File "/home/runner/Tinsml/venv/lib/python3.8/site-packages/quart/templating.py", line 108, in _render
    rendered_template = await template.render_async(context)
  File "/home/runner/Tinsml/venv/lib/python3.8/site-packages/jinja2/environment.py", line 1324, in render_async
    return self.environment.handle_exception()
  File "/home/runner/Tinsml/venv/lib/python3.8/site-packages/jinja2/environment.py", line 936, in handle_exception
    raise rewrite_traceback_stack(source=source)
  File "/home/runner/Tinsml/venv/lib/python3.8/site-packages/jinja2/environment.py", line 1321, in <listcomp>
    [n async for n in self.root_render_func(ctx)]  # type: ignore
  File "/home/runner/Tinsml/templates/home.html", line 1, in top-level template code
    {% extends 'base.html' %}
  File "/home/runner/Tinsml/venv/lib/python3.8/site-packages/jinja2/environment.py", line 936, in handle_exception
    raise rewrite_traceback_stack(source=source)
  File "/home/runner/Tinsml/templates/base.html", line 424, in template
    {% block ct_nobulma}
jinja2.exceptions.TemplateSyntaxError: unexpected '}'
Exception on request GET /
Traceback (most recent call last):
  File "/home/runner/Tinsml/venv/lib/python3.8/site-packages/quart/app.py", line 1489, in handle_request
    return await self.full_dispatch_request(request_context)
  File "/home/runner/Tinsml/venv/lib/python3.8/site-packages/quart/app.py", line 1514, in full_dispatch_request
    result = await self.handle_user_exception(error)
  File "/home/runner/Tinsml/venv/lib/python3.8/site-packages/quart/app.py", line 964, in handle_user_exception
    raise error
  File "/home/runner/Tinsml/venv/lib/python3.8/site-packages/quart/app.py", line 1512, in full_dispatch_request
    result = await self.dispatch_request(request_context)
  File "/home/runner/Tinsml/venv/lib/python3.8/site-packages/quart/app.py", line 1557, in dispatch_request
    return await self.ensure_async(handler)(**request_.view_args)
  File "server.py", line 18, in home
    return await render_template("home.html")
  File "/home/runner/Tinsml/venv/lib/python3.8/site-packages/quart/templating.py", line 91, in render_template
    return await _render(template, context, current_app._get_current_object())  # type: ignore
  File "/home/runner/Tinsml/venv/lib/python3.8/site-packages/quart/templating.py", line 108, in _render
    rendered_template = await template.render_async(context)
  File "/home/runner/Tinsml/venv/lib/python3.8/site-packages/jinja2/environment.py", line 1324, in render_async
    return self.environment.handle_exception()
  File "/home/runner/Tinsml/venv/lib/python3.8/site-packages/jinja2/environment.py", line 936, in handle_exception
    raise rewrite_traceback_stack(source=source)
  File "/home/runner/Tinsml/venv/lib/python3.8/site-packages/jinja2/environment.py", line 1321, in <listcomp>
    [n async for n in self.root_render_func(ctx)]  # type: ignore
  File "/home/runner/Tinsml/templates/home.html", line 1, in top-level template code
    {% extends 'base.html' %}
  File "/home/runner/Tinsml/venv/lib/python3.8/site-packages/jinja2/environment.py", line 936, in handle_exception
    raise rewrite_traceback_stack(source=source)
  File "/home/runner/Tinsml/templates/base.html", line 448, in template
    <a class="link-1" href="{{ url_for('home') }}">Trang chủ</a>
jinja2.exceptions.TemplateSyntaxError: Unexpected end of template. Jinja was looking for the following tags: 'endblock'. The innermost block that needs to be closed is 'block'.
Exception on request GET /
Traceback (most recent call last):
  File "/home/runner/Tinsml/venv/lib/python3.8/site-packages/quart/app.py", line 1489, in handle_request
    return await self.full_dispatch_request(request_context)
  File "/home/runner/Tinsml/venv/lib/python3.8/site-packages/quart/app.py", line 1514, in full_dispatch_request
    result = await self.handle_user_exception(error)
  File "/home/runner/Tinsml/venv/lib/python3.8/site-packages/quart/app.py", line 964, in handle_user_exception
    raise error
  File "/home/runner/Tinsml/venv/lib/python3.8/site-packages/quart/app.py", line 1512, in full_dispatch_request
    result = await self.dispatch_request(request_context)
  File "/home/runner/Tinsml/venv/lib/python3.8/site-packages/quart/app.py", line 1557, in dispatch_request
    return await self.ensure_async(handler)(**request_.view_args)
  File "server.py", line 18, in home
    return await render_template("home.html")
  File "/home/runner/Tinsml/venv/lib/python3.8/site-packages/quart/templating.py", line 91, in render_template
    return await _render(template, context, current_app._get_current_object())  # type: ignore
  File "/home/runner/Tinsml/venv/lib/python3.8/site-packages/quart/templating.py", line 108, in _render
    rendered_template = await template.render_async(context)
  File "/home/runner/Tinsml/venv/lib/python3.8/site-packages/jinja2/environment.py", line 1324, in render_async
    return self.environment.handle_exception()
  File "/home/runner/Tinsml/venv/lib/python3.8/site-packages/jinja2/environment.py", line 936, in handle_exception
    raise rewrite_traceback_stack(source=source)
  File "/home/runner/Tinsml/venv/lib/python3.8/site-packages/jinja2/environment.py", line 1321, in <listcomp>
    [n async for n in self.root_render_func(ctx)]  # type: ignore
  File "/home/runner/Tinsml/templates/home.html", line 1, in top-level template code
    {% extends 'base.html' %}
  File "/home/runner/Tinsml/venv/lib/python3.8/site-packages/jinja2/environment.py", line 936, in handle_exception
    raise rewrite_traceback_stack(source=source)
  File "/home/runner/Tinsml/templates/base.html", line 448, in template
    <a class="link-1" href="{{ url_for('home') }}">Trang chủ</a>
jinja2.exceptions.TemplateSyntaxError: Unexpected end of template. Jinja was looking for the following tags: 'endblock'. The innermost block that needs to be closed is 'block'.
Exception on request GET /chs/ztdata
Traceback (most recent call last):
  File "/home/runner/Tinsml/venv/lib/python3.8/site-packages/quart/app.py", line 1489, in handle_request
    return await self.full_dispatch_request(request_context)
  File "/home/runner/Tinsml/venv/lib/python3.8/site-packages/quart/app.py", line 1514, in full_dispatch_request
    result = await self.handle_user_exception(error)
  File "/home/runner/Tinsml/venv/lib/python3.8/site-packages/quart/app.py", line 964, in handle_user_exception
    raise error
  File "/home/runner/Tinsml/venv/lib/python3.8/site-packages/quart/app.py", line 1512, in full_dispatch_request
    result = await self.dispatch_request(request_context)
  File "/home/runner/Tinsml/venv/lib/python3.8/site-packages/quart/app.py", line 1557, in dispatch_request
    return await self.ensure_async(handler)(**request_.view_args)
  File "server.py", line 152, in ztdatahome
    total.append(s)
AttributeError: 'str' object has no attribute 'append'
Exception on request GET /about/
Traceback (most recent call last):
  File "/home/runner/Tinsml/venv/lib/python3.8/site-packages/quart/app.py", line 1489, in handle_request
    return await self.full_dispatch_request(request_context)
  File "/home/runner/Tinsml/venv/lib/python3.8/site-packages/quart/app.py", line 1514, in full_dispatch_request
    result = await self.handle_user_exception(error)
  File "/home/runner/Tinsml/venv/lib/python3.8/site-packages/quart/app.py", line 964, in handle_user_exception
    raise error
  File "/home/runner/Tinsml/venv/lib/python3.8/site-packages/quart/app.py", line 1512, in full_dispatch_request
    result = await self.dispatch_request(request_context)
  File "/home/runner/Tinsml/venv/lib/python3.8/site-packages/quart/app.py", line 1557, in dispatch_request
    return await self.ensure_async(handler)(**request_.view_args)
  File "server.py", line 23, in about
    return await render_template("about.html")
  File "/home/runner/Tinsml/venv/lib/python3.8/site-packages/quart/templating.py", line 90, in render_template
    template = current_app.jinja_env.get_or_select_template(template_name_or_list)  # type: ignore
  File "/home/runner/Tinsml/venv/lib/python3.8/site-packages/jinja2/environment.py", line 1081, in get_or_select_template
    return self.get_template(template_name_or_list, parent, globals)
  File "/home/runner/Tinsml/venv/lib/python3.8/site-packages/jinja2/environment.py", line 1010, in get_template
    return self._load_template(name, globals)
  File "/home/runner/Tinsml/venv/lib/python3.8/site-packages/jinja2/environment.py", line 969, in _load_template
    template = self.loader.load(self, name, self.make_globals(globals))
  File "/home/runner/Tinsml/venv/lib/python3.8/site-packages/jinja2/loaders.py", line 138, in load
    code = environment.compile(source, name, filename)
  File "/home/runner/Tinsml/venv/lib/python3.8/site-packages/jinja2/environment.py", line 768, in compile
    self.handle_exception(source=source_hint)
  File "/home/runner/Tinsml/venv/lib/python3.8/site-packages/jinja2/environment.py", line 936, in handle_exception
    raise rewrite_traceback_stack(source=source)
  File "/home/runner/Tinsml/templates/about.html", line 2, in template
    {% block title &}{% endblock %}
jinja2.exceptions.TemplateSyntaxError: unexpected char '&' at 41
Exception on request GET /chs/
Traceback (most recent call last):
  File "/home/runner/Tinsml/venv/lib/python3.8/site-packages/quart/app.py", line 1489, in handle_request
    return await self.full_dispatch_request(request_context)
  File "/home/runner/Tinsml/venv/lib/python3.8/site-packages/quart/app.py", line 1514, in full_dispatch_request
    result = await self.handle_user_exception(error)
  File "/home/runner/Tinsml/venv/lib/python3.8/site-packages/quart/app.py", line 964, in handle_user_exception
    raise error
  File "/home/runner/Tinsml/venv/lib/python3.8/site-packages/quart/app.py", line 1512, in full_dispatch_request
    result = await self.dispatch_request(request_context)
  File "/home/runner/Tinsml/venv/lib/python3.8/site-packages/quart/app.py", line 1557, in dispatch_request
    return await self.ensure_async(handler)(**request_.view_args)
  File "/home/runner/Tinsml/server.py", line 66, in chs
    return await render_template("chs.html",games=g)
  File "/home/runner/Tinsml/venv/lib/python3.8/site-packages/quart/templating.py", line 90, in render_template
    template = current_app.jinja_env.get_or_select_template(template_name_or_list)  # type: ignore
  File "/home/runner/Tinsml/venv/lib/python3.8/site-packages/jinja2/environment.py", line 1081, in get_or_select_template
    return self.get_template(template_name_or_list, parent, globals)
  File "/home/runner/Tinsml/venv/lib/python3.8/site-packages/jinja2/environment.py", line 1010, in get_template
    return self._load_template(name, globals)
  File "/home/runner/Tinsml/venv/lib/python3.8/site-packages/jinja2/environment.py", line 969, in _load_template
    template = self.loader.load(self, name, self.make_globals(globals))
  File "/home/runner/Tinsml/venv/lib/python3.8/site-packages/jinja2/loaders.py", line 138, in load
    code = environment.compile(source, name, filename)
  File "/home/runner/Tinsml/venv/lib/python3.8/site-packages/jinja2/environment.py", line 768, in compile
    self.handle_exception(source=source_hint)
  File "/home/runner/Tinsml/venv/lib/python3.8/site-packages/jinja2/environment.py", line 936, in handle_exception
    raise rewrite_traceback_stack(source=source)
  File "/home/runner/Tinsml/templates/chs.html", line 9, in template
    {% endfor %}
jinja2.exceptions.TemplateSyntaxError: Encountered unknown tag 'endfor'. You probably made a nesting mistake. Jinja is expecting this tag, but currently looking for 'endif'. The innermost block that needs to be closed is 'if'.
Exception on request GET /chs/
Traceback (most recent call last):
  File "/home/runner/Tinsml/venv/lib/python3.8/site-packages/quart/app.py", line 1489, in handle_request
    return await self.full_dispatch_request(request_context)
  File "/home/runner/Tinsml/venv/lib/python3.8/site-packages/quart/app.py", line 1514, in full_dispatch_request
    result = await self.handle_user_exception(error)
  File "/home/runner/Tinsml/venv/lib/python3.8/site-packages/quart/app.py", line 964, in handle_user_exception
    raise error
  File "/home/runner/Tinsml/venv/lib/python3.8/site-packages/quart/app.py", line 1512, in full_dispatch_request
    result = await self.dispatch_request(request_context)
  File "/home/runner/Tinsml/venv/lib/python3.8/site-packages/quart/app.py", line 1557, in dispatch_request
    return await self.ensure_async(handler)(**request_.view_args)
  File "/home/runner/Tinsml/server.py", line 66, in chs
    return await render_template("chs.html",games=g)
  File "/home/runner/Tinsml/venv/lib/python3.8/site-packages/quart/templating.py", line 90, in render_template
    template = current_app.jinja_env.get_or_select_template(template_name_or_list)  # type: ignore
  File "/home/runner/Tinsml/venv/lib/python3.8/site-packages/jinja2/environment.py", line 1081, in get_or_select_template
    return self.get_template(template_name_or_list, parent, globals)
  File "/home/runner/Tinsml/venv/lib/python3.8/site-packages/jinja2/environment.py", line 1010, in get_template
    return self._load_template(name, globals)
  File "/home/runner/Tinsml/venv/lib/python3.8/site-packages/jinja2/environment.py", line 969, in _load_template
    template = self.loader.load(self, name, self.make_globals(globals))
  File "/home/runner/Tinsml/venv/lib/python3.8/site-packages/jinja2/loaders.py", line 138, in load
    code = environment.compile(source, name, filename)
  File "/home/runner/Tinsml/venv/lib/python3.8/site-packages/jinja2/environment.py", line 768, in compile
    self.handle_exception(source=source_hint)
  File "/home/runner/Tinsml/venv/lib/python3.8/site-packages/jinja2/environment.py", line 936, in handle_exception
    raise rewrite_traceback_stack(source=source)
  File "/home/runner/Tinsml/templates/chs.html", line 8, in template
    <strong>{{game}</strong>
jinja2.exceptions.TemplateSyntaxError: unexpected '}'
Exception on request GET /
Traceback (most recent call last):
  File "/home/runner/Tinsml/venv/lib/python3.8/site-packages/quart/app.py", line 1489, in handle_request
    return await self.full_dispatch_request(request_context)
  File "/home/runner/Tinsml/venv/lib/python3.8/site-packages/quart/app.py", line 1514, in full_dispatch_request
    result = await self.handle_user_exception(error)
  File "/home/runner/Tinsml/venv/lib/python3.8/site-packages/quart/app.py", line 964, in handle_user_exception
    raise error
  File "/home/runner/Tinsml/venv/lib/python3.8/site-packages/quart/app.py", line 1512, in full_dispatch_request
    result = await self.dispatch_request(request_context)
  File "/home/runner/Tinsml/venv/lib/python3.8/site-packages/quart/app.py", line 1557, in dispatch_request
    return await self.ensure_async(handler)(**request_.view_args)
  File "server.py", line 18, in home
    return await render_template("home.html")
  File "/home/runner/Tinsml/venv/lib/python3.8/site-packages/quart/templating.py", line 91, in render_template
    return await _render(template, context, current_app._get_current_object())  # type: ignore
  File "/home/runner/Tinsml/venv/lib/python3.8/site-packages/quart/templating.py", line 108, in _render
    rendered_template = await template.render_async(context)
  File "/home/runner/Tinsml/venv/lib/python3.8/site-packages/jinja2/environment.py", line 1324, in render_async
    return self.environment.handle_exception()
  File "/home/runner/Tinsml/venv/lib/python3.8/site-packages/jinja2/environment.py", line 936, in handle_exception
    raise rewrite_traceback_stack(source=source)
  File "/home/runner/Tinsml/venv/lib/python3.8/site-packages/jinja2/environment.py", line 1321, in <listcomp>
    [n async for n in self.root_render_func(ctx)]  # type: ignore
  File "/home/runner/Tinsml/templates/home.html", line 1, in top-level template code
    {% extends 'base.html' %}
  File "/home/runner/Tinsml/venv/lib/python3.8/site-packages/jinja2/environment.py", line 936, in handle_exception
    raise rewrite_traceback_stack(source=source)
  File "/home/runner/Tinsml/templates/base.html", line 377, in template
    <a class="navbar-item" href="status.{{domain)}}">
jinja2.exceptions.TemplateSyntaxError: unexpected ')'
Exception on request GET /
Traceback (most recent call last):
  File "/home/runner/Tinsml/venv/lib/python3.8/site-packages/quart/app.py", line 1489, in handle_request
    return await self.full_dispatch_request(request_context)
  File "/home/runner/Tinsml/venv/lib/python3.8/site-packages/quart/app.py", line 1514, in full_dispatch_request
    result = await self.handle_user_exception(error)
  File "/home/runner/Tinsml/venv/lib/python3.8/site-packages/quart/app.py", line 964, in handle_user_exception
    raise error
  File "/home/runner/Tinsml/venv/lib/python3.8/site-packages/quart/app.py", line 1512, in full_dispatch_request
    result = await self.dispatch_request(request_context)
  File "/home/runner/Tinsml/venv/lib/python3.8/site-packages/quart/app.py", line 1557, in dispatch_request
    return await self.ensure_async(handler)(**request_.view_args)
  File "server.py", line 18, in home
    return await render_template("home.html")
  File "/home/runner/Tinsml/venv/lib/python3.8/site-packages/quart/templating.py", line 91, in render_template
    return await _render(template, context, current_app._get_current_object())  # type: ignore
  File "/home/runner/Tinsml/venv/lib/python3.8/site-packages/quart/templating.py", line 108, in _render
    rendered_template = await template.render_async(context)
  File "/home/runner/Tinsml/venv/lib/python3.8/site-packages/jinja2/environment.py", line 1324, in render_async
    return self.environment.handle_exception()
  File "/home/runner/Tinsml/venv/lib/python3.8/site-packages/jinja2/environment.py", line 936, in handle_exception
    raise rewrite_traceback_stack(source=source)
  File "/home/runner/Tinsml/venv/lib/python3.8/site-packages/jinja2/environment.py", line 1321, in <listcomp>
    [n async for n in self.root_render_func(ctx)]  # type: ignore
  File "/home/runner/Tinsml/templates/home.html", line 1, in top-level template code
    {% extends 'base.html' %}
  File "/home/runner/Tinsml/venv/lib/python3.8/site-packages/jinja2/environment.py", line 936, in handle_exception
    raise rewrite_traceback_stack(source=source)
  File "/home/runner/Tinsml/templates/base.html", line 377, in template
    <a class="navbar-item" href="status.{{domain)}}">
jinja2.exceptions.TemplateSyntaxError: unexpected ')'
Exception on request GET /
Traceback (most recent call last):
  File "/home/runner/Tinsml/venv/lib/python3.8/site-packages/quart/app.py", line 1489, in handle_request
    return await self.full_dispatch_request(request_context)
  File "/home/runner/Tinsml/venv/lib/python3.8/site-packages/quart/app.py", line 1514, in full_dispatch_request
    result = await self.handle_user_exception(error)
  File "/home/runner/Tinsml/venv/lib/python3.8/site-packages/quart/app.py", line 964, in handle_user_exception
    raise error
  File "/home/runner/Tinsml/venv/lib/python3.8/site-packages/quart/app.py", line 1512, in full_dispatch_request
    result = await self.dispatch_request(request_context)
  File "/home/runner/Tinsml/venv/lib/python3.8/site-packages/quart/app.py", line 1557, in dispatch_request
    return await self.ensure_async(handler)(**request_.view_args)
  File "server.py", line 18, in home
    return await render_template("home.html")
  File "/home/runner/Tinsml/venv/lib/python3.8/site-packages/quart/templating.py", line 91, in render_template
    return await _render(template, context, current_app._get_current_object())  # type: ignore
  File "/home/runner/Tinsml/venv/lib/python3.8/site-packages/quart/templating.py", line 108, in _render
    rendered_template = await template.render_async(context)
  File "/home/runner/Tinsml/venv/lib/python3.8/site-packages/jinja2/environment.py", line 1324, in render_async
    return self.environment.handle_exception()
  File "/home/runner/Tinsml/venv/lib/python3.8/site-packages/jinja2/environment.py", line 936, in handle_exception
    raise rewrite_traceback_stack(source=source)
  File "/home/runner/Tinsml/venv/lib/python3.8/site-packages/jinja2/environment.py", line 1321, in <listcomp>
    [n async for n in self.root_render_func(ctx)]  # type: ignore
  File "/home/runner/Tinsml/templates/home.html", line 1, in top-level template code
    {% extends 'base.html' %}
  File "/home/runner/Tinsml/venv/lib/python3.8/site-packages/jinja2/environment.py", line 936, in handle_exception
    raise rewrite_traceback_stack(source=source)
  File "/home/runner/Tinsml/templates/base.html", line 377, in template
    <a class="navbar-item" href="status.{{domain)}}">
jinja2.exceptions.TemplateSyntaxError: unexpected ')'
Exception on request GET /
Traceback (most recent call last):
  File "/home/runner/Tinsml/venv/lib/python3.8/site-packages/quart/app.py", line 1489, in handle_request
    return await self.full_dispatch_request(request_context)
  File "/home/runner/Tinsml/venv/lib/python3.8/site-packages/quart/app.py", line 1514, in full_dispatch_request
    result = await self.handle_user_exception(error)
  File "/home/runner/Tinsml/venv/lib/python3.8/site-packages/quart/app.py", line 964, in handle_user_exception
    raise error
  File "/home/runner/Tinsml/venv/lib/python3.8/site-packages/quart/app.py", line 1512, in full_dispatch_request
    result = await self.dispatch_request(request_context)
  File "/home/runner/Tinsml/venv/lib/python3.8/site-packages/quart/app.py", line 1557, in dispatch_request
    return await self.ensure_async(handler)(**request_.view_args)
  File "server.py", line 18, in home
    return await render_template("home.html")
  File "/home/runner/Tinsml/venv/lib/python3.8/site-packages/quart/templating.py", line 91, in render_template
    return await _render(template, context, current_app._get_current_object())  # type: ignore
  File "/home/runner/Tinsml/venv/lib/python3.8/site-packages/quart/templating.py", line 108, in _render
    rendered_template = await template.render_async(context)
  File "/home/runner/Tinsml/venv/lib/python3.8/site-packages/jinja2/environment.py", line 1324, in render_async
    return self.environment.handle_exception()
  File "/home/runner/Tinsml/venv/lib/python3.8/site-packages/jinja2/environment.py", line 936, in handle_exception
    raise rewrite_traceback_stack(source=source)
  File "/home/runner/Tinsml/venv/lib/python3.8/site-packages/jinja2/environment.py", line 1321, in <listcomp>
    [n async for n in self.root_render_func(ctx)]  # type: ignore
  File "/home/runner/Tinsml/templates/home.html", line 1, in top-level template code
    {% extends 'base.html' %}
  File "/home/runner/Tinsml/venv/lib/python3.8/site-packages/jinja2/environment.py", line 936, in handle_exception
    raise rewrite_traceback_stack(source=source)
  File "/home/runner/Tinsml/templates/base.html", line 377, in template
    <a class="navbar-item" href="status.{{domain)}}">
jinja2.exceptions.TemplateSyntaxError: unexpected ')'
Exception on request HEAD /
Traceback (most recent call last):
  File "/home/runner/Tinsml/venv/lib/python3.8/site-packages/quart/app.py", line 1489, in handle_request
    return await self.full_dispatch_request(request_context)
  File "/home/runner/Tinsml/venv/lib/python3.8/site-packages/quart/app.py", line 1514, in full_dispatch_request
    result = await self.handle_user_exception(error)
  File "/home/runner/Tinsml/venv/lib/python3.8/site-packages/quart/app.py", line 964, in handle_user_exception
    raise error
  File "/home/runner/Tinsml/venv/lib/python3.8/site-packages/quart/app.py", line 1512, in full_dispatch_request
    result = await self.dispatch_request(request_context)
  File "/home/runner/Tinsml/venv/lib/python3.8/site-packages/quart/app.py", line 1557, in dispatch_request
    return await self.ensure_async(handler)(**request_.view_args)
  File "server.py", line 18, in home
    return await render_template("home.html")
  File "/home/runner/Tinsml/venv/lib/python3.8/site-packages/quart/templating.py", line 91, in render_template
    return await _render(template, context, current_app._get_current_object())  # type: ignore
  File "/home/runner/Tinsml/venv/lib/python3.8/site-packages/quart/templating.py", line 108, in _render
    rendered_template = await template.render_async(context)
  File "/home/runner/Tinsml/venv/lib/python3.8/site-packages/jinja2/environment.py", line 1324, in render_async
    return self.environment.handle_exception()
  File "/home/runner/Tinsml/venv/lib/python3.8/site-packages/jinja2/environment.py", line 936, in handle_exception
    raise rewrite_traceback_stack(source=source)
  File "/home/runner/Tinsml/venv/lib/python3.8/site-packages/jinja2/environment.py", line 1321, in <listcomp>
    [n async for n in self.root_render_func(ctx)]  # type: ignore
  File "/home/runner/Tinsml/templates/home.html", line 1, in top-level template code
    {% extends 'base.html' %}
  File "/home/runner/Tinsml/venv/lib/python3.8/site-packages/jinja2/environment.py", line 936, in handle_exception
    raise rewrite_traceback_stack(source=source)
  File "/home/runner/Tinsml/templates/base.html", line 377, in template
    <a class="navbar-item" href="status.{{domain)}}">
jinja2.exceptions.TemplateSyntaxError: unexpected ')'
Exception on request GET /
Traceback (most recent call last):
  File "/home/runner/Tinsml/venv/lib/python3.8/site-packages/quart/app.py", line 1489, in handle_request
    return await self.full_dispatch_request(request_context)
  File "/home/runner/Tinsml/venv/lib/python3.8/site-packages/quart/app.py", line 1514, in full_dispatch_request
    result = await self.handle_user_exception(error)
  File "/home/runner/Tinsml/venv/lib/python3.8/site-packages/quart/app.py", line 964, in handle_user_exception
    raise error
  File "/home/runner/Tinsml/venv/lib/python3.8/site-packages/quart/app.py", line 1512, in full_dispatch_request
    result = await self.dispatch_request(request_context)
  File "/home/runner/Tinsml/venv/lib/python3.8/site-packages/quart/app.py", line 1557, in dispatch_request
    return await self.ensure_async(handler)(**request_.view_args)
  File "server.py", line 18, in home
    return await render_template("home.html")
  File "/home/runner/Tinsml/venv/lib/python3.8/site-packages/quart/templating.py", line 91, in render_template
    return await _render(template, context, current_app._get_current_object())  # type: ignore
  File "/home/runner/Tinsml/venv/lib/python3.8/site-packages/quart/templating.py", line 108, in _render
    rendered_template = await template.render_async(context)
  File "/home/runner/Tinsml/venv/lib/python3.8/site-packages/jinja2/environment.py", line 1324, in render_async
    return self.environment.handle_exception()
  File "/home/runner/Tinsml/venv/lib/python3.8/site-packages/jinja2/environment.py", line 936, in handle_exception
    raise rewrite_traceback_stack(source=source)
  File "/home/runner/Tinsml/venv/lib/python3.8/site-packages/jinja2/environment.py", line 1321, in <listcomp>
    [n async for n in self.root_render_func(ctx)]  # type: ignore
  File "/home/runner/Tinsml/templates/home.html", line 1, in top-level template code
    {% extends 'base.html' %}
  File "/home/runner/Tinsml/venv/lib/python3.8/site-packages/jinja2/environment.py", line 936, in handle_exception
    raise rewrite_traceback_stack(source=source)
  File "/home/runner/Tinsml/templates/base.html", line 377, in template
    <a class="navbar-item" href="status.{{domain)}}">
jinja2.exceptions.TemplateSyntaxError: unexpected ')'
Exception on request GET /
Traceback (most recent call last):
  File "/home/runner/Tinsml/venv/lib/python3.8/site-packages/quart/app.py", line 1489, in handle_request
    return await self.full_dispatch_request(request_context)
  File "/home/runner/Tinsml/venv/lib/python3.8/site-packages/quart/app.py", line 1514, in full_dispatch_request
    result = await self.handle_user_exception(error)
  File "/home/runner/Tinsml/venv/lib/python3.8/site-packages/quart/app.py", line 964, in handle_user_exception
    raise error
  File "/home/runner/Tinsml/venv/lib/python3.8/site-packages/quart/app.py", line 1512, in full_dispatch_request
    result = await self.dispatch_request(request_context)
  File "/home/runner/Tinsml/venv/lib/python3.8/site-packages/quart/app.py", line 1557, in dispatch_request
    return await self.ensure_async(handler)(**request_.view_args)
  File "server.py", line 18, in home
    return await render_template("home.html")
  File "/home/runner/Tinsml/venv/lib/python3.8/site-packages/quart/templating.py", line 91, in render_template
    return await _render(template, context, current_app._get_current_object())  # type: ignore
  File "/home/runner/Tinsml/venv/lib/python3.8/site-packages/quart/templating.py", line 108, in _render
    rendered_template = await template.render_async(context)
  File "/home/runner/Tinsml/venv/lib/python3.8/site-packages/jinja2/environment.py", line 1324, in render_async
    return self.environment.handle_exception()
  File "/home/runner/Tinsml/venv/lib/python3.8/site-packages/jinja2/environment.py", line 936, in handle_exception
    raise rewrite_traceback_stack(source=source)
  File "/home/runner/Tinsml/venv/lib/python3.8/site-packages/jinja2/environment.py", line 1321, in <listcomp>
    [n async for n in self.root_render_func(ctx)]  # type: ignore
  File "/home/runner/Tinsml/templates/home.html", line 1, in top-level template code
    {% extends 'base.html' %}
  File "/home/runner/Tinsml/venv/lib/python3.8/site-packages/jinja2/environment.py", line 936, in handle_exception
    raise rewrite_traceback_stack(source=source)
  File "/home/runner/Tinsml/templates/base.html", line 377, in template
    <a class="navbar-item" href="status.{{domain)}}">
jinja2.exceptions.TemplateSyntaxError: unexpected ')'
